Workbook

Sheet Read Me
A1: How this tracker works
A4: What to edit
A5: White cells | B5: Inputs. Owners update these.
A6: Grey cells | B6: Formulas. Do not edit.
A7: Last updated (Accounts) | B7: Owners update this date every time they touch the row. Rows older than 7 days are flagged.
A8: Rules the Dashboard enforces
A9: Gate breach (RED) | B9: Stage is Onboarding or later and Go / No Go is not Go.
A10: Gate breach (RED) | B10: Any pre-onboarding step marked Skipped.
A11: Gate breach (RED) | B11: A committed onboarding date is entered before Go / No Go is Go. No date is committed until the gate is green.
A12: Gate breach (RED) | B12: Stage is Done but 'All scanners returning data' is empty. Done means every enabled scanner returns data, not Terraform applied.
A13: Watch item (AMBER) | B13: No onboarding record linked; no named engineer during Pre or Onboarding; retro not held within 48 hours of the scanner date; next action missing or overdue; row not updated in 7 days; a Done step with no evidence link where evidence is required.
A14: How to add an account
A15: Add a row in Accounts. In Checklist, copy the 16 rows of any account to the bottom, change the account name and reset Status to Not started. Fill Named owner for each step; Row flag fills from its formula.
A17: How the runbook stays in sync
A18: The Steps tab mirrors the runbook . Change it only when a retro changes the runbook. Checklist rows carry the step text; when the runbook changes a step, update Steps and the matching Checklist rows.

Sheet Steps and Roles
A1: Step ID | B1: Phase | C1: Step | D1: Owner role | E1: Exit criterion | F1: Evidence required (Y/N) | G1: Evidence / asset expected | H1: Deviations logged | I1: Rank key (helper)
A2: P1 | B2: Pre | C2: Copy the Onboarding Record template and link it in the Accounts tab | D2: TSE | E2: Record link populated in Accounts tab | F2: Y | G2: Onboarding Record link | H2: =COUNTIF(Deviations!$C$2:$C$151,A2) -> 0 | I2: =H2+(100-ROW())/1000 -> 0.098
A3: P2 | B3: Pre | C3: Technical assessment of the environment | D3: TSE | E3: Section A environment profile complete | F3: Y | G3: Onboarding Record, Section A | H3: =COUNTIF(Deviations!$C$2:$C$151,A3) -> 0 | I3: =H3+(100-ROW())/1000 -> 0.097
A4: P3 | B4: Pre | C4: Permission pre-flight run on named admins | D4: TSE | E4: Pre-flight output attached; every failure resolved or logged as a deviation | F4: Y | G4: Pre-flight script output | H4: =COUNTIF(Deviations!$C$2:$C$151,A4) -> 0 | I4: =H4+(100-ROW())/1000 -> 0.096
A5: P4 | B5: Pre | C5: Engineering review of regions, services, APIs and SCPs; known noise suppressed in the back end before Terraform | D5: Named engineer | E5: Suppression applied before Terraform runs (pre-facto, not post-onboarding cleanup) | F5: Y | G5: Engineering review notes / suppression confirmation | H5: =COUNTIF(Deviations!$C$2:$C$151,A5) -> 0 | I5: =H5+(100-ROW())/1000 -> 0.095
A6: P5 | B6: Pre | C6: Branch decisions recorded (Outpost vs Cloud Scan, StackSet vs per-account Terraform, Azure vs AWS, Fed tenant, least-privilege Azure) | D6: TSE | E6: Section B branch decisions complete | F6: Y | G6: Onboarding Record, Section B | H6: =COUNTIF(Deviations!$C$2:$C$151,A6) -> 0 | I6: =H6+(100-ROW())/1000 -> 0.094
A7: P6 | B7: Pre | C7: Workshop with TSE, TPE and PS on the wizard and the decision branches | D7: TSE | E7: Workshop held; date recorded | F7: N | H7: =COUNTIF(Deviations!$C$2:$C$151,A7) -> 0 | I7: =H7+(100-ROW())/1000 -> 0.093
A8: P7 | B8: Pre | C8: Customer briefed on findings vs. issues and on not editing templates | D8: TSE | E8: Briefing held with the customer's named admins | F8: N | H8: =COUNTIF(Deviations!$C$2:$C$151,A8) -> 0 | I8: =H8+(100-ROW())/1000 -> 0.092
A9: P8 | B9: Pre | C9: Go / No Go with a committed date | D9: TSE + PS | E9: P1 to P7 Done or N/A; Go recorded in Accounts tab; date committed. If any gate item is not met, the date moves | F9: Y | G9: Onboarding Record, Section C | H9: =COUNTIF(Deviations!$C$2:$C$151,A9) -> 0 | I9: =H9+(100-ROW())/1000 -> 0.091
A10: D1 | B10: During | C10: First account or subscription onboarded and validated end to end before the org | D10: PS | E10: One account or subscription ingesting with every enabled scanner returning data | F10: Y | G10: Validation evidence | H10: =COUNTIF(Deviations!$C$2:$C$151,A10) -> 0 | I10: =H10+(100-ROW())/1000 -> 0.09
A11: D2 | B11: During | C11: Tiger team plus named engineer on the call reading errors live | D11: Named engineer | E11: Named engineer attended the event call | F11: N | H11: =COUNTIF(Deviations!$C$2:$C$151,A11) -> 0 | I11: =H11+(100-ROW())/1000 -> 0.089
A12: D3 | B12: During | C12: Every deviation logged against the step where it occurred | D12: PS | E12: Every deviation in the Deviations tab with a step ID | F12: N | H12: =COUNTIF(Deviations!$C$2:$C$151,A12) -> 0 | I12: =H12+(100-ROW())/1000 -> 0.088
A13: D4 | B13: During | C13: Org onboarding run; Terraform applied | D13: PS | E13: Terraform apply date recorded in Accounts tab (this is not the exit) | F13: N | H13: =COUNTIF(Deviations!$C$2:$C$151,A13) -> 0 | I13: =H13+(100-ROW())/1000 -> 0.087
A14: V1 | B14: Post | C14: Validation checklist run against the definition of done | D14: TSE + PS | E14: All accounts ingesting and every enabled scanner returning data; date recorded in Accounts tab | F14: Y | G14: Onboarding Record, Section E | H14: =COUNTIF(Deviations!$C$2:$C$151,A14) -> 0 | I14: =H14+(100-ROW())/1000 -> 0.086
A15: V2 | B15: Post | C15: Enablement session on findings vs. issues | D15: TSE | E15: Session held | F15: N | H15: =COUNTIF(Deviations!$C$2:$C$151,A15) -> 0 | I15: =H15+(100-ROW())/1000 -> 0.085
A16: V3 | B16: Post | C16: Retro within 48 hours of V1 | D16: TSE | E16: Retro held; outputs logged to runbook change log (Vitaliy), docs feedback log and pre-flight script | F16: Y | G16: Onboarding Record, Section F | H16: =COUNTIF(Deviations!$C$2:$C$151,A16) -> 0 | I16: =H16+(100-ROW())/1000 -> 0.084
A17: V4 | B17: Post | C17: Handover to CS | D17: TSE | E17: Section G complete; CS owner named | F17: Y | G17: Onboarding Record, Section G | H17: =COUNTIF(Deviations!$C$2:$C$151,A17) -> 0 | I17: =H17+(100-ROW())/1000 -> 0.083

Sheet Dashboard
A2: =SUMPRODUCT(((Accounts!$J$2:$J$21="Onboarding")+(Accounts!$J$2:$J$21="Post-onboarding")+(Accounts!$J$2:$J$21="Done"))*1) -> 8 | C2: =SUMPRODUCT((Accounts!$J$2:$J$21="Done")*(Accounts!$R$2:$R$21="")) -> 0 | E2: =IFERROR(MEDIAN($G$15:$G$27),"–") -> – | G2: =COUNTIF($I$15:$I$27,">0") -> 8 | I2: =COUNTA(Deviations!$B$2:$B$151) -> 0
A3: ="Events run (of "&COUNTA(Accounts!$B$2:$B$21)&")" -> Events run (of 13) | C3: Clean exits | E3: Median days | G3: Accounts with a gate breach | I3: Deviations logged
A4: Stage is Onboarding or later | C4: Done with no open blocker | G4: See Health = RED | I4: All accounts
A6: Pipeline by stage
A7: Not started | B7: Pre-onboarding | C7: Onboarding | D7: Post-onboarding | E7: Done | F7: On hold
A8: =COUNTIF(Accounts!$J$2:$J$21,"Not started") -> 4 | B8: =COUNTIF(Accounts!$J$2:$J$21,"Pre-onboarding") -> 1 | C8: =COUNTIF(Accounts!$J$2:$J$21,"Onboarding") -> 6 | D8: =COUNTIF(Accounts!$J$2:$J$21,"Post-onboarding") -> 1 | E8: =COUNTIF(Accounts!$J$2:$J$21,"Done") -> 1 | F8: =COUNTIF(Accounts!$J$2:$J$21,"On hold") -> 0
A13: Account spotlight: gate compliance and next action
A14: Account | B14: Stage | C14: PS | D14: TSE | E14: Pre steps complete | F14: Go / No Go | G14: Days, Terraform to all scanners | H14: Deviations | I14: Gate breaches | J14: Watch items | K14: Gate Check | L14: Flags | M14: Next action | N14: Owner | O14: Due
A15: =IF(Accounts!$B2="","",Accounts!$B2) -> Zoom Video | B15: =IF($A15="","",Accounts!$J2&"") -> Onboarding | C15: =IF($A15="","",Accounts!$F2&"") -> Matthew Dombrowski | D15: =IF($A15="","",Accounts!$G2&"") -> Z Yu | E15: =IF($A15="","",(COUNTIFS(Checklist!$A$2:$A$400,$A15,Checklist!$B$2:$B$400,"P*",Checklist!$F$2:$F$400,"Done")+COUNTIFS(Checklist!$A$2:$A$400,$A15,Checklist!$B$2:$B$400,"P*",Checklist!$F$2:$F$400,"N/A"))&" / "&COUNTIFS(Checklist!$A$2:$A$400,$A15,Checklist!$B$2:$B$400,"P*")) -> 0 / 8 | F15: =IF($A15="","",IF(Accounts!$K2="","Not held",Accounts!$K2)) -> Not held | G15: =IF(OR($A15="",Accounts!$N2="",Accounts!$O2=""),"",Accounts!$O2-Accounts!$N2) | H15: =IF($A15="","",COUNTIF(Deviations!$B$2:$B$151,$A15)) -> 0 | I15: =IF($A15="","",(AND(OR(Accounts!$J2="Onboarding",Accounts!$J2="Post-onboarding",Accounts!$J2="Done"),Accounts!$K2<>"Go"))*1+(COUNTIFS(Checklist!$A$2:$A$400,$A15,Checklist!$B$2:$B$400,"P*",Checklist!$F$2:$F$400,"Skipped")>0)*1+(AND(Accounts!$M2<>"",Accounts!$K2<>"Go"))*1+(AND(Accounts!$J2="Done",Accounts!$O2=""))*1) -> 2 | J15: =IF($A15="","",(AND(Accounts!$J2<>"Not started",Accounts!$I2=""))*1+(AND(OR(Accounts!$J2="Pre-onboarding",Accounts!$J2="Onboarding"),Accounts!$H2=""))*1+(IF(Accounts!$O2="",FALSE,AND(Accounts!$P2="",TODAY()-Accounts!$O2>2)))*1+(IF(Accounts!$U2="",FALSE,AND(Accounts!$U2<TODAY(),Accounts!$J2<>"Done")))*1+(IF(Accounts!$V2="",TRUE,TODAY()-Accounts!$V2>7))*1+(AND(Accounts!$S2="",Accounts!$J2<>"Done"))*1+(COUNTIFS(Checklist!$A$2:$A$400,$A15,Checklist!$K$2:$K$400,"*Evidence missing*")>0)*1) -> 3 | K15: =IF($A15="","",IF(I15>0,"RED",IF(J15>0,"AMBER","GREEN"))) -> RED | L15: =IF($A15="","",IF(AND(OR(Accounts!$J2="Onboarding",Accounts!$J2="Post-onboarding",Accounts!$J2="Done"),Accounts!$K2<>"Go"),"Onboarding started without a Go"&CHAR(10),"")&IF(COUNTIFS(Checklist!$A$2:$A$400,$A15,Checklist!$B$2:$B$400,"P*",Checklist!$F$2:$F$400,"Skipped")>0,"Pre-onboarding step skipped"&CHAR(10),"")&IF(AND(Accounts!$M2<>"",Accounts!$K2<>"Go"),"Date committed before the gate is green"&CHAR(10),"")&IF(AND(Accounts!$J2="Done",Accounts!$O2=""),"Marked Done before all scanners return data"&CHAR(10),"")&IF(AND(Accounts!$J2<>"Not started",Accounts!$I2=""),"No onboarding record linked"&CHAR(10),"")&IF(AND(OR(Accounts!$J2="Pre-onboarding",Accounts!$J2="Onboarding"),Accounts!$H2=""),"No named engineer"&CHAR(10),"")&IF(IF(Accounts!$O2="",FALSE,AND(Accounts!$P2="",TODAY()-Accounts!$O2>2)),"Retro overdue (48h rule)"&CHAR(10),"")&IF(IF(Accounts!$U2="",FALSE,AND(Accounts!$U2<TODAY(),Accounts!$J2<>"Done")),"Next action overdue"&CHAR(10),"")&IF(IF(Accounts!$V2="",TRUE,TODAY()-Accounts!$V2>7),"Not updated in 7+ days"&CHAR(10),"")&IF(AND(Accounts!$S2="",Accounts!$J2<>"Done"),"No next action set"&CHAR(10),"")&IF(COUNTIFS(Checklist!$A$2:$A$400,$A15,Checklist!$K$2:$K$400,"*Evidence missing*")>0,"Done step missing evidence"&CHAR(10),"")) -> Onboarding started without a Go Date committed before the gate is green No onboarding record linked No named engineer Not updated in 7+ days | M15: =IF($A15="","",Accounts!$S2&"") -> Once issues are resolved, we can continue onboarding GCP and Azure (if customer wants to in migration) | N15: =IF($A15="","",Accounts!$T2&"") -> Matt-PS Mark - EE Zoom - Cloud Ops | O15: =IF(OR($A15="",Accounts!$U2=""),"",Accounts!$U2) -> TBD
A16: =IF(Accounts!$B3="","",Accounts!$B3) -> Broadcom | B16: =IF($A16="","",Accounts!$J3&"") -> Onboarding | C16: =IF($A16="","",Accounts!$F3&"") -> Stephen Lovett | D16: =IF($A16="","",Accounts!$G3&"") -> Z Yu | E16: =IF($A16="","",(COUNTIFS(Checklist!$A$2:$A$400,$A16,Checklist!$B$2:$B$400,"P*",Checklist!$F$2:$F$400,"Done")+COUNTIFS(Checklist!$A$2:$A$400,$A16,Checklist!$B$2:$B$400,"P*",Checklist!$F$2:$F$400,"N/A"))&" / "&COUNTIFS(Checklist!$A$2:$A$400,$A16,Checklist!$B$2:$B$400,"P*")) -> 3 / 8 | F16: =IF($A16="","",IF(Accounts!$K3="","Not held",Accounts!$K3)) -> Not held | G16: =IF(OR($A16="",Accounts!$N3="",Accounts!$O3=""),"",Accounts!$O3-Accounts!$N3) | H16: =IF($A16="","",COUNTIF(Deviations!$B$2:$B$151,$A16)) -> 0 | I16: =IF($A16="","",(AND(OR(Accounts!$J3="Onboarding",Accounts!$J3="Post-onboarding",Accounts!$J3="Done"),Accounts!$K3<>"Go"))*1+(COUNTIFS(Checklist!$A$2:$A$400,$A16,Checklist!$B$2:$B$400,"P*",Checklist!$F$2:$F$400,"Skipped")>0)*1+(AND(Accounts!$M3<>"",Accounts!$K3<>"Go"))*1+(AND(Accounts!$J3="Done",Accounts!$O3=""))*1) -> 1 | J16: =IF($A16="","",(AND(Accounts!$J3<>"Not started",Accounts!$I3=""))*1+(AND(OR(Accounts!$J3="Pre-onboarding",Accounts!$J3="Onboarding"),Accounts!$H3=""))*1+(IF(Accounts!$O3="",FALSE,AND(Accounts!$P3="",TODAY()-Accounts!$O3>2)))*1+(IF(Accounts!$U3="",FALSE,AND(Accounts!$U3<TODAY(),Accounts!$J3<>"Done")))*1+(IF(Accounts!$V3="",TRUE,TODAY()-Accounts!$V3>7))*1+(AND(Accounts!$S3="",Accounts!$J3<>"Done"))*1+(COUNTIFS(Checklist!$A$2:$A$400,$A16,Checklist!$K$2:$K$400,"*Evidence missing*")>0)*1) -> 3 | K16: =IF($A16="","",IF(I16>0,"RED",IF(J16>0,"AMBER","GREEN"))) -> RED | L16: =IF($A16="","",IF(AND(OR(Accounts!$J3="Onboarding",Accounts!$J3="Post-onboarding",Accounts!$J3="Done"),Accounts!$K3<>"Go"),"Onboarding started without a Go"&CHAR(10),"")&IF(COUNTIFS(Checklist!$A$2:$A$400,$A16,Checklist!$B$2:$B$400,"P*",Checklist!$F$2:$F$400,"Skipped")>0,"Pre-onboarding step skipped"&CHAR(10),"")&IF(AND(Accounts!$M3<>"",Accounts!$K3<>"Go"),"Date committed before the gate is green"&CHAR(10),"")&IF(AND(Accounts!$J3="Done",Accounts!$O3=""),"Marked Done before all scanners return data"&CHAR(10),"")&IF(AND(Accounts!$J3<>"Not started",Accounts!$I3=""),"No onboarding record linked"&CHAR(10),"")&IF(AND(OR(Accounts!$J3="Pre-onboarding",Accounts!$J3="Onboarding"),Accounts!$H3=""),"No named engineer"&CHAR(10),"")&IF(IF(Accounts!$O3="",FALSE,AND(Accounts!$P3="",TODAY()-Accounts!$O3>2)),"Retro overdue (48h rule)"&CHAR(10),"")&IF(IF(Accounts!$U3="",FALSE,AND(Accounts!$U3<TODAY(),Accounts!$J3<>"Done")),"Next action overdue"&CHAR(10),"")&IF(IF(Accounts!$V3="",TRUE,TODAY()-Accounts!$V3>7),"Not updated in 7+ days"&CHAR(10),"")&IF(AND(Accounts!$S3="",Accounts!$J3<>"Done"),"No next action set"&CHAR(10),"")&IF(COUNTIFS(Checklist!$A$2:$A$400,$A16,Checklist!$K$2:$K$400,"*Evidence missing*")>0,"Done step missing evidence"&CHAR(10),"")) -> Onboarding started without a Go No named engineer Not updated in 7+ days Done step missing evidence | M16: =IF($A16="","",Accounts!$S3&"") -> Pending customer's internal ticket to have cloud admin review outpost terraform files and apply. | N16: =IF($A16="","",Accounts!$T3&"") | O16: =IF(OR($A16="",Accounts!$U3=""),"",Accounts!$U3)
A17: =IF(Accounts!$B4="","",Accounts!$B4) -> Telecom Guatemala | B17: =IF($A17="","",Accounts!$J4&"") -> Done | C17: =IF($A17="","",Accounts!$F4&"") -> Ariel Nin | D17: =IF($A17="","",Accounts!$G4&"") -> Fabio Cezar (DC) | E17: =IF($A17="","",(COUNTIFS(Checklist!$A$2:$A$400,$A17,Checklist!$B$2:$B$400,"P*",Checklist!$F$2:$F$400,"Done")+COUNTIFS(Checklist!$A$2:$A$400,$A17,Checklist!$B$2:$B$400,"P*",Checklist!$F$2:$F$400,"N/A"))&" / "&COUNTIFS(Checklist!$A$2:$A$400,$A17,Checklist!$B$2:$B$400,"P*")) -> 4 / 8 | F17: =IF($A17="","",IF(Accounts!$K4="","Not held",Accounts!$K4)) -> Not held | G17: =IF(OR($A17="",Accounts!$N4="",Accounts!$O4=""),"",Accounts!$O4-Accounts!$N4) -> #VALUE! | H17: =IF($A17="","",COUNTIF(Deviations!$B$2:$B$151,$A17)) -> 0 | I17: =IF($A17="","",(AND(OR(Accounts!$J4="Onboarding",Accounts!$J4="Post-onboarding",Accounts!$J4="Done"),Accounts!$K4<>"Go"))*1+(COUNTIFS(Checklist!$A$2:$A$400,$A17,Checklist!$B$2:$B$400,"P*",Checklist!$F$2:$F$400,"Skipped")>0)*1+(AND(Accounts!$M4<>"",Accounts!$K4<>"Go"))*1+(AND(Accounts!$J4="Done",Accounts!$O4=""))*1) -> 2 | J17: =IF($A17="","",(AND(Accounts!$J4<>"Not started",Accounts!$I4=""))*1+(AND(OR(Accounts!$J4="Pre-onboarding",Accounts!$J4="Onboarding"),Accounts!$H4=""))*1+(IF(Accounts!$O4="",FALSE,AND(Accounts!$P4="",TODAY()-Accounts!$O4>2)))*1+(IF(Accounts!$U4="",FALSE,AND(Accounts!$U4<TODAY(),Accounts!$J4<>"Done")))*1+(IF(Accounts!$V4="",TRUE,TODAY()-Accounts!$V4>7))*1+(AND(Accounts!$S4="",Accounts!$J4<>"Done"))*1+(COUNTIFS(Checklist!$A$2:$A$400,$A17,Checklist!$K$2:$K$400,"*Evidence missing*")>0)*1) -> 2 | K17: =IF($A17="","",IF(I17>0,"RED",IF(J17>0,"AMBER","GREEN"))) -> RED | L17: =IF($A17="","",IF(AND(OR(Accounts!$J4="Onboarding",Accounts!$J4="Post-onboarding",Accounts!$J4="Done"),Accounts!$K4<>"Go"),"Onboarding started without a Go"&CHAR(10),"")&IF(COUNTIFS(Checklist!$A$2:$A$400,$A17,Checklist!$B$2:$B$400,"P*",Checklist!$F$2:$F$400,"Skipped")>0,"Pre-onboarding step skipped"&CHAR(10),"")&IF(AND(Accounts!$M4<>"",Accounts!$K4<>"Go"),"Date committed before the gate is green"&CHAR(10),"")&IF(AND(Accounts!$J4="Done",Accounts!$O4=""),"Marked Done before all scanners return data"&CHAR(10),"")&IF(AND(Accounts!$J4<>"Not started",Accounts!$I4=""),"No onboarding record linked"&CHAR(10),"")&IF(AND(OR(Accounts!$J4="Pre-onboarding",Accounts!$J4="Onboarding"),Accounts!$H4=""),"No named engineer"&CHAR(10),"")&IF(IF(Accounts!$O4="",FALSE,AND(Accounts!$P4="",TODAY()-Accounts!$O4>2)),"Retro overdue (48h rule)"&CHAR(10),"")&IF(IF(Accounts!$U4="",FALSE,AND(Accounts!$U4<TODAY(),Accounts!$J4<>"Done")),"Next action overdue"&CHAR(10),"")&IF(IF(Accounts!$V4="",TRUE,TODAY()-Accounts!$V4>7),"Not updated in 7+ days"&CHAR(10),"")&IF(AND(Accounts!$S4="",Accounts!$J4<>"Done"),"No next action set"&CHAR(10),"")&IF(COUNTIFS(Checklist!$A$2:$A$400,$A17,Checklist!$K$2:$K$400,"*Evidence missing*")>0,"Done step missing evidence"&CHAR(10),"")) -> Onboarding started without a Go Date committed before the gate is green Retro overdue (48h rule) Not updated in 7+ days | M17: =IF($A17="","",Accounts!$S4&"") -> Continue the Cortex Cloud CSPM deployment | N17: =IF($A17="","",Accounts!$T4&"") -> Ariel Nin - Professional Services | O17: =IF(OR($A17="",Accounts!$U4=""),"",Accounts!$U4) -> 10/05 onwards
A18: =IF(Accounts!$B5="","",Accounts!$B5) -> FIS Global | B18: =IF($A18="","",Accounts!$J5&"") -> Not started | C18: =IF($A18="","",Accounts!$F5&"") -> Stephen Lovett | D18: =IF($A18="","",Accounts!$G5&"") -> Harold Moore (DC) | E18: =IF($A18="","",(COUNTIFS(Checklist!$A$2:$A$400,$A18,Checklist!$B$2:$B$400,"P*",Checklist!$F$2:$F$400,"Done")+COUNTIFS(Checklist!$A$2:$A$400,$A18,Checklist!$B$2:$B$400,"P*",Checklist!$F$2:$F$400,"N/A"))&" / "&COUNTIFS(Checklist!$A$2:$A$400,$A18,Checklist!$B$2:$B$400,"P*")) -> 0 / 8 | F18: =IF($A18="","",IF(Accounts!$K5="","Not held",Accounts!$K5)) -> Not held | G18: =IF(OR($A18="",Accounts!$N5="",Accounts!$O5=""),"",Accounts!$O5-Accounts!$N5) | H18: =IF($A18="","",COUNTIF(Deviations!$B$2:$B$151,$A18)) -> 0 | I18: =IF($A18="","",(AND(OR(Accounts!$J5="Onboarding",Accounts!$J5="Post-onboarding",Accounts!$J5="Done"),Accounts!$K5<>"Go"))*1+(COUNTIFS(Checklist!$A$2:$A$400,$A18,Checklist!$B$2:$B$400,"P*",Checklist!$F$2:$F$400,"Skipped")>0)*1+(AND(Accounts!$M5<>"",Accounts!$K5<>"Go"))*1+(AND(Accounts!$J5="Done",Accounts!$O5=""))*1) -> 0 | J18: =IF($A18="","",(AND(Accounts!$J5<>"Not started",Accounts!$I5=""))*1+(AND(OR(Accounts!$J5="Pre-onboarding",Accounts!$J5="Onboarding"),Accounts!$H5=""))*1+(IF(Accounts!$O5="",FALSE,AND(Accounts!$P5="",TODAY()-Accounts!$O5>2)))*1+(IF(Accounts!$U5="",FALSE,AND(Accounts!$U5<TODAY(),Accounts!$J5<>"Done")))*1+(IF(Accounts!$V5="",TRUE,TODAY()-Accounts!$V5>7))*1+(AND(Accounts!$S5="",Accounts!$J5<>"Done"))*1+(COUNTIFS(Checklist!$A$2:$A$400,$A18,Checklist!$K$2:$K$400,"*Evidence missing*")>0)*1) -> 1 | K18: =IF($A18="","",IF(I18>0,"RED",IF(J18>0,"AMBER","GREEN"))) -> AMBER | L18: =IF($A18="","",IF(AND(OR(Accounts!$J5="Onboarding",Accounts!$J5="Post-onboarding",Accounts!$J5="Done"),Accounts!$K5<>"Go"),"Onboarding started without a Go"&CHAR(10),"")&IF(COUNTIFS(Checklist!$A$2:$A$400,$A18,Checklist!$B$2:$B$400,"P*",Checklist!$F$2:$F$400,"Skipped")>0,"Pre-onboarding step skipped"&CHAR(10),"")&IF(AND(Accounts!$M5<>"",Accounts!$K5<>"Go"),"Date committed before the gate is green"&CHAR(10),"")&IF(AND(Accounts!$J5="Done",Accounts!$O5=""),"Marked Done before all scanners return data"&CHAR(10),"")&IF(AND(Accounts!$J5<>"Not started",Accounts!$I5=""),"No onboarding record linked"&CHAR(10),"")&IF(AND(OR(Accounts!$J5="Pre-onboarding",Accounts!$J5="Onboarding"),Accounts!$H5=""),"No named engineer"&CHAR(10),"")&IF(IF(Accounts!$O5="",FALSE,AND(Accounts!$P5="",TODAY()-Accounts!$O5>2)),"Retro overdue (48h rule)"&CHAR(10),"")&IF(IF(Accounts!$U5="",FALSE,AND(Accounts!$U5<TODAY(),Accounts!$J5<>"Done")),"Next action overdue"&CHAR(10),"")&IF(IF(Accounts!$V5="",TRUE,TODAY()-Accounts!$V5>7),"Not updated in 7+ days"&CHAR(10),"")&IF(AND(Accounts!$S5="",Accounts!$J5<>"Done"),"No next action set"&CHAR(10),"")&IF(COUNTIFS(Checklist!$A$2:$A$400,$A18,Checklist!$K$2:$K$400,"*Evidence missing*")>0,"Done step missing evidence"&CHAR(10),"")) -> Not updated in 7+ days | M18: =IF($A18="","",Accounts!$S5&"") -> Customer has onboarded all their Cloud Providers however seeing errors and warnings. Customer has indicated expanding security capabilities and pivot towards outposts. | N18: =IF($A18="","",Accounts!$T5&"") | O18: =IF(OR($A18="",Accounts!$U5=""),"",Accounts!$U5)
A19: =IF(Accounts!$B6="","",Accounts!$B6) -> Fidelity | B19: =IF($A19="","",Accounts!$J6&"") -> Pre-onboarding | C19: =IF($A19="","",Accounts!$F6&"") -> Stephen Lovett | D19: =IF($A19="","",Accounts!$G6&"") -> Ravi Badana | E19: =IF($A19="","",(COUNTIFS(Checklist!$A$2:$A$400,$A19,Checklist!$B$2:$B$400,"P*",Checklist!$F$2:$F$400,"Done")+COUNTIFS(Checklist!$A$2:$A$400,$A19,Checklist!$B$2:$B$400,"P*",Checklist!$F$2:$F$400,"N/A"))&" / "&COUNTIFS(Checklist!$A$2:$A$400,$A19,Checklist!$B$2:$B$400,"P*")) -> 0 / 8 | F19: =IF($A19="","",IF(Accounts!$K6="","Not held",Accounts!$K6)) -> Not held | G19: =IF(OR($A19="",Accounts!$N6="",Accounts!$O6=""),"",Accounts!$O6-Accounts!$N6) | H19: =IF($A19="","",COUNTIF(Deviations!$B$2:$B$151,$A19)) -> 0 | I19: =IF($A19="","",(AND(OR(Accounts!$J6="Onboarding",Accounts!$J6="Post-onboarding",Accounts!$J6="Done"),Accounts!$K6<>"Go"))*1+(COUNTIFS(Checklist!$A$2:$A$400,$A19,Checklist!$B$2:$B$400,"P*",Checklist!$F$2:$F$400,"Skipped")>0)*1+(AND(Accounts!$M6<>"",Accounts!$K6<>"Go"))*1+(AND(Accounts!$J6="Done",Accounts!$O6=""))*1) -> 0 | J19: =IF($A19="","",(AND(Accounts!$J6<>"Not started",Accounts!$I6=""))*1+(AND(OR(Accounts!$J6="Pre-onboarding",Accounts!$J6="Onboarding"),Accounts!$H6=""))*1+(IF(Accounts!$O6="",FALSE,AND(Accounts!$P6="",TODAY()-Accounts!$O6>2)))*1+(IF(Accounts!$U6="",FALSE,AND(Accounts!$U6<TODAY(),Accounts!$J6<>"Done")))*1+(IF(Accounts!$V6="",TRUE,TODAY()-Accounts!$V6>7))*1+(AND(Accounts!$S6="",Accounts!$J6<>"Done"))*1+(COUNTIFS(Checklist!$A$2:$A$400,$A19,Checklist!$K$2:$K$400,"*Evidence missing*")>0)*1) -> 2 | K19: =IF($A19="","",IF(I19>0,"RED",IF(J19>0,"AMBER","GREEN"))) -> AMBER | L19: =IF($A19="","",IF(AND(OR(Accounts!$J6="Onboarding",Accounts!$J6="Post-onboarding",Accounts!$J6="Done"),Accounts!$K6<>"Go"),"Onboarding started without a Go"&CHAR(10),"")&IF(COUNTIFS(Checklist!$A$2:$A$400,$A19,Checklist!$B$2:$B$400,"P*",Checklist!$F$2:$F$400,"Skipped")>0,"Pre-onboarding step skipped"&CHAR(10),"")&IF(AND(Accounts!$M6<>"",Accounts!$K6<>"Go"),"Date committed before the gate is green"&CHAR(10),"")&IF(AND(Accounts!$J6="Done",Accounts!$O6=""),"Marked Done before all scanners return data"&CHAR(10),"")&IF(AND(Accounts!$J6<>"Not started",Accounts!$I6=""),"No onboarding record linked"&CHAR(10),"")&IF(AND(OR(Accounts!$J6="Pre-onboarding",Accounts!$J6="Onboarding"),Accounts!$H6=""),"No named engineer"&CHAR(10),"")&IF(IF(Accounts!$O6="",FALSE,AND(Accounts!$P6="",TODAY()-Accounts!$O6>2)),"Retro overdue (48h rule)"&CHAR(10),"")&IF(IF(Accounts!$U6="",FALSE,AND(Accounts!$U6<TODAY(),Accounts!$J6<>"Done")),"Next action overdue"&CHAR(10),"")&IF(IF(Accounts!$V6="",TRUE,TODAY()-Accounts!$V6>7),"Not updated in 7+ days"&CHAR(10),"")&IF(AND(Accounts!$S6="",Accounts!$J6<>"Done"),"No next action set"&CHAR(10),"")&IF(COUNTIFS(Checklist!$A$2:$A$400,$A19,Checklist!$K$2:$K$400,"*Evidence missing*")>0,"Done step missing evidence"&CHAR(10),"")) -> No named engineer Not updated in 7+ days | M19: =IF($A19="","",Accounts!$S6&"") -> Customer is conducting POV | N19: =IF($A19="","",Accounts!$T6&"") | O19: =IF(OR($A19="",Accounts!$U6=""),"",Accounts!$U6)
A20: =IF(Accounts!$B7="","",Accounts!$B7) -> DOI | B20: =IF($A20="","",Accounts!$J7&"") -> Not started | C20: =IF($A20="","",Accounts!$F7&"") -> Stephen Lovett | D20: =IF($A20="","",Accounts!$G7&"") | E20: =IF($A20="","",(COUNTIFS(Checklist!$A$2:$A$400,$A20,Checklist!$B$2:$B$400,"P*",Checklist!$F$2:$F$400,"Done")+COUNTIFS(Checklist!$A$2:$A$400,$A20,Checklist!$B$2:$B$400,"P*",Checklist!$F$2:$F$400,"N/A"))&" / "&COUNTIFS(Checklist!$A$2:$A$400,$A20,Checklist!$B$2:$B$400,"P*")) -> 0 / 8 | F20: =IF($A20="","",IF(Accounts!$K7="","Not held",Accounts!$K7)) -> Not held | G20: =IF(OR($A20="",Accounts!$N7="",Accounts!$O7=""),"",Accounts!$O7-Accounts!$N7) | H20: =IF($A20="","",COUNTIF(Deviations!$B$2:$B$151,$A20)) -> 0 | I20: =IF($A20="","",(AND(OR(Accounts!$J7="Onboarding",Accounts!$J7="Post-onboarding",Accounts!$J7="Done"),Accounts!$K7<>"Go"))*1+(COUNTIFS(Checklist!$A$2:$A$400,$A20,Checklist!$B$2:$B$400,"P*",Checklist!$F$2:$F$400,"Skipped")>0)*1+(AND(Accounts!$M7<>"",Accounts!$K7<>"Go"))*1+(AND(Accounts!$J7="Done",Accounts!$O7=""))*1) -> 0 | J20: =IF($A20="","",(AND(Accounts!$J7<>"Not started",Accounts!$I7=""))*1+(AND(OR(Accounts!$J7="Pre-onboarding",Accounts!$J7="Onboarding"),Accounts!$H7=""))*1+(IF(Accounts!$O7="",FALSE,AND(Accounts!$P7="",TODAY()-Accounts!$O7>2)))*1+(IF(Accounts!$U7="",FALSE,AND(Accounts!$U7<TODAY(),Accounts!$J7<>"Done")))*1+(IF(Accounts!$V7="",TRUE,TODAY()-Accounts!$V7>7))*1+(AND(Accounts!$S7="",Accounts!$J7<>"Done"))*1+(COUNTIFS(Checklist!$A$2:$A$400,$A20,Checklist!$K$2:$K$400,"*Evidence missing*")>0)*1) -> 1 | K20: =IF($A20="","",IF(I20>0,"RED",IF(J20>0,"AMBER","GREEN"))) -> AMBER | L20: =IF($A20="","",IF(AND(OR(Accounts!$J7="Onboarding",Accounts!$J7="Post-onboarding",Accounts!$J7="Done"),Accounts!$K7<>"Go"),"Onboarding started without a Go"&CHAR(10),"")&IF(COUNTIFS(Checklist!$A$2:$A$400,$A20,Checklist!$B$2:$B$400,"P*",Checklist!$F$2:$F$400,"Skipped")>0,"Pre-onboarding step skipped"&CHAR(10),"")&IF(AND(Accounts!$M7<>"",Accounts!$K7<>"Go"),"Date committed before the gate is green"&CHAR(10),"")&IF(AND(Accounts!$J7="Done",Accounts!$O7=""),"Marked Done before all scanners return data"&CHAR(10),"")&IF(AND(Accounts!$J7<>"Not started",Accounts!$I7=""),"No onboarding record linked"&CHAR(10),"")&IF(AND(OR(Accounts!$J7="Pre-onboarding",Accounts!$J7="Onboarding"),Accounts!$H7=""),"No named engineer"&CHAR(10),"")&IF(IF(Accounts!$O7="",FALSE,AND(Accounts!$P7="",TODAY()-Accounts!$O7>2)),"Retro overdue (48h rule)"&CHAR(10),"")&IF(IF(Accounts!$U7="",FALSE,AND(Accounts!$U7<TODAY(),Accounts!$J7<>"Done")),"Next action overdue"&CHAR(10),"")&IF(IF(Accounts!$V7="",TRUE,TODAY()-Accounts!$V7>7),"Not updated in 7+ days"&CHAR(10),"")&IF(AND(Accounts!$S7="",Accounts!$J7<>"Done"),"No next action set"&CHAR(10),"")&IF(COUNTIFS(Checklist!$A$2:$A$400,$A20,Checklist!$K$2:$K$400,"*Evidence missing*")>0,"Done step missing evidence"&CHAR(10),"")) -> Not updated in 7+ days | M20: =IF($A20="","",Accounts!$S7&"") -> On hold | N20: =IF($A20="","",Accounts!$T7&"") | O20: =IF(OR($A20="",Accounts!$U7=""),"",Accounts!$U7)
A21: =IF(Accounts!$B8="","",Accounts!$B8) -> Marriott | B21: =IF($A21="","",Accounts!$J8&"") -> Onboarding | C21: =IF($A21="","",Accounts!$F8&"") -> Bliss Jourdan | D21: =IF($A21="","",Accounts!$G8&"") -> Khizar Karim | E21: =IF($A21="","",(COUNTIFS(Checklist!$A$2:$A$400,$A21,Checklist!$B$2:$B$400,"P*",Checklist!$F$2:$F$400,"Done")+COUNTIFS(Checklist!$A$2:$A$400,$A21,Checklist!$B$2:$B$400,"P*",Checklist!$F$2:$F$400,"N/A"))&" / "&COUNTIFS(Checklist!$A$2:$A$400,$A21,Checklist!$B$2:$B$400,"P*")) -> 0 / 8 | F21: =IF($A21="","",IF(Accounts!$K8="","Not held",Accounts!$K8)) -> Not held | G21: =IF(OR($A21="",Accounts!$N8="",Accounts!$O8=""),"",Accounts!$O8-Accounts!$N8) | H21: =IF($A21="","",COUNTIF(Deviations!$B$2:$B$151,$A21)) -> 0 | I21: =IF($A21="","",(AND(OR(Accounts!$J8="Onboarding",Accounts!$J8="Post-onboarding",Accounts!$J8="Done"),Accounts!$K8<>"Go"))*1+(COUNTIFS(Checklist!$A$2:$A$400,$A21,Checklist!$B$2:$B$400,"P*",Checklist!$F$2:$F$400,"Skipped")>0)*1+(AND(Accounts!$M8<>"",Accounts!$K8<>"Go"))*1+(AND(Accounts!$J8="Done",Accounts!$O8=""))*1) -> 2 | J21: =IF($A21="","",(AND(Accounts!$J8<>"Not started",Accounts!$I8=""))*1+(AND(OR(Accounts!$J8="Pre-onboarding",Accounts!$J8="Onboarding"),Accounts!$H8=""))*1+(IF(Accounts!$O8="",FALSE,AND(Accounts!$P8="",TODAY()-Accounts!$O8>2)))*1+(IF(Accounts!$U8="",FALSE,AND(Accounts!$U8<TODAY(),Accounts!$J8<>"Done")))*1+(IF(Accounts!$V8="",TRUE,TODAY()-Accounts!$V8>7))*1+(AND(Accounts!$S8="",Accounts!$J8<>"Done"))*1+(COUNTIFS(Checklist!$A$2:$A$400,$A21,Checklist!$K$2:$K$400,"*Evidence missing*")>0)*1) -> 3 | K21: =IF($A21="","",IF(I21>0,"RED",IF(J21>0,"AMBER","GREEN"))) -> RED | L21: =IF($A21="","",IF(AND(OR(Accounts!$J8="Onboarding",Accounts!$J8="Post-onboarding",Accounts!$J8="Done"),Accounts!$K8<>"Go"),"Onboarding started without a Go"&CHAR(10),"")&IF(COUNTIFS(Checklist!$A$2:$A$400,$A21,Checklist!$B$2:$B$400,"P*",Checklist!$F$2:$F$400,"Skipped")>0,"Pre-onboarding step skipped"&CHAR(10),"")&IF(AND(Accounts!$M8<>"",Accounts!$K8<>"Go"),"Date committed before the gate is green"&CHAR(10),"")&IF(AND(Accounts!$J8="Done",Accounts!$O8=""),"Marked Done before all scanners return data"&CHAR(10),"")&IF(AND(Accounts!$J8<>"Not started",Accounts!$I8=""),"No onboarding record linked"&CHAR(10),"")&IF(AND(OR(Accounts!$J8="Pre-onboarding",Accounts!$J8="Onboarding"),Accounts!$H8=""),"No named engineer"&CHAR(10),"")&IF(IF(Accounts!$O8="",FALSE,AND(Accounts!$P8="",TODAY()-Accounts!$O8>2)),"Retro overdue (48h rule)"&CHAR(10),"")&IF(IF(Accounts!$U8="",FALSE,AND(Accounts!$U8<TODAY(),Accounts!$J8<>"Done")),"Next action overdue"&CHAR(10),"")&IF(IF(Accounts!$V8="",TRUE,TODAY()-Accounts!$V8>7),"Not updated in 7+ days"&CHAR(10),"")&IF(AND(Accounts!$S8="",Accounts!$J8<>"Done"),"No next action set"&CHAR(10),"")&IF(COUNTIFS(Checklist!$A$2:$A$400,$A21,Checklist!$K$2:$K$400,"*Evidence missing*")>0,"Done step missing evidence"&CHAR(10),"")) -> Onboarding started without a Go Date committed before the gate is green No named engineer Not updated in 7+ days No next action set | M21: =IF($A21="","",Accounts!$S8&"") | N21: =IF($A21="","",Accounts!$T8&"") | O21: =IF(OR($A21="",Accounts!$U8=""),"",Accounts!$U8)
A22: =IF(Accounts!$B9="","",Accounts!$B9) -> Honeywell International | B22: =IF($A22="","",Accounts!$J9&"") -> Onboarding | C22: =IF($A22="","",Accounts!$F9&"") -> Kirk Preston | D22: =IF($A22="","",Accounts!$G9&"") | E22: =IF($A22="","",(COUNTIFS(Checklist!$A$2:$A$400,$A22,Checklist!$B$2:$B$400,"P*",Checklist!$F$2:$F$400,"Done")+COUNTIFS(Checklist!$A$2:$A$400,$A22,Checklist!$B$2:$B$400,"P*",Checklist!$F$2:$F$400,"N/A"))&" / "&COUNTIFS(Checklist!$A$2:$A$400,$A22,Checklist!$B$2:$B$400,"P*")) -> 0 / 0 | F22: =IF($A22="","",IF(Accounts!$K9="","Not held",Accounts!$K9)) -> Not held | G22: =IF(OR($A22="",Accounts!$N9="",Accounts!$O9=""),"",Accounts!$O9-Accounts!$N9) -> #VALUE! | H22: =IF($A22="","",COUNTIF(Deviations!$B$2:$B$151,$A22)) -> 0 | I22: =IF($A22="","",(AND(OR(Accounts!$J9="Onboarding",Accounts!$J9="Post-onboarding",Accounts!$J9="Done"),Accounts!$K9<>"Go"))*1+(COUNTIFS(Checklist!$A$2:$A$400,$A22,Checklist!$B$2:$B$400,"P*",Checklist!$F$2:$F$400,"Skipped")>0)*1+(AND(Accounts!$M9<>"",Accounts!$K9<>"Go"))*1+(AND(Accounts!$J9="Done",Accounts!$O9=""))*1) -> 2 | J22: =IF($A22="","",(AND(Accounts!$J9<>"Not started",Accounts!$I9=""))*1+(AND(OR(Accounts!$J9="Pre-onboarding",Accounts!$J9="Onboarding"),Accounts!$H9=""))*1+(IF(Accounts!$O9="",FALSE,AND(Accounts!$P9="",TODAY()-Accounts!$O9>2)))*1+(IF(Accounts!$U9="",FALSE,AND(Accounts!$U9<TODAY(),Accounts!$J9<>"Done")))*1+(IF(Accounts!$V9="",TRUE,TODAY()-Accounts!$V9>7))*1+(AND(Accounts!$S9="",Accounts!$J9<>"Done"))*1+(COUNTIFS(Checklist!$A$2:$A$400,$A22,Checklist!$K$2:$K$400,"*Evidence missing*")>0)*1) -> #VALUE! | K22: =IF($A22="","",IF(I22>0,"RED",IF(J22>0,"AMBER","GREEN"))) -> RED | L22: =IF($A22="","",IF(AND(OR(Accounts!$J9="Onboarding",Accounts!$J9="Post-onboarding",Accounts!$J9="Done"),Accounts!$K9<>"Go"),"Onboarding started without a Go"&CHAR(10),"")&IF(COUNTIFS(Checklist!$A$2:$A$400,$A22,Checklist!$B$2:$B$400,"P*",Checklist!$F$2:$F$400,"Skipped")>0,"Pre-onboarding step skipped"&CHAR(10),"")&IF(AND(Accounts!$M9<>"",Accounts!$K9<>"Go"),"Date committed before the gate is green"&CHAR(10),"")&IF(AND(Accounts!$J9="Done",Accounts!$O9=""),"Marked Done before all scanners return data"&CHAR(10),"")&IF(AND(Accounts!$J9<>"Not started",Accounts!$I9=""),"No onboarding record linked"&CHAR(10),"")&IF(AND(OR(Accounts!$J9="Pre-onboarding",Accounts!$J9="Onboarding"),Accounts!$H9=""),"No named engineer"&CHAR(10),"")&IF(IF(Accounts!$O9="",FALSE,AND(Accounts!$P9="",TODAY()-Accounts!$O9>2)),"Retro overdue (48h rule)"&CHAR(10),"")&IF(IF(Accounts!$U9="",FALSE,AND(Accounts!$U9<TODAY(),Accounts!$J9<>"Done")),"Next action overdue"&CHAR(10),"")&IF(IF(Accounts!$V9="",TRUE,TODAY()-Accounts!$V9>7),"Not updated in 7+ days"&CHAR(10),"")&IF(AND(Accounts!$S9="",Accounts!$J9<>"Done"),"No next action set"&CHAR(10),"")&IF(COUNTIFS(Checklist!$A$2:$A$400,$A22,Checklist!$K$2:$K$400,"*Evidence missing*")>0,"Done step missing evidence"&CHAR(10),"")) -> #VALUE! | M22: =IF($A22="","",Accounts!$S9&"") -> Download CSP templates for internal review proactively. | N22: =IF($A22="","",Accounts!$T9&"") -> TBD | O22: =IF(OR($A22="",Accounts!$U9=""),"",Accounts!$U9) -> TBD
A23: =IF(Accounts!$B10="","",Accounts!$B10) -> Salesforce - ESS org | B23: =IF($A23="","",Accounts!$J10&"") -> Not started | C23: =IF($A23="","",Accounts!$F10&"") -> Bliss Jourdan | D23: =IF($A23="","",Accounts!$G10&"") -> Khizar Karim | E23: =IF($A23="","",(COUNTIFS(Checklist!$A$2:$A$400,$A23,Checklist!$B$2:$B$400,"P*",Checklist!$F$2:$F$400,"Done")+COUNTIFS(Checklist!$A$2:$A$400,$A23,Checklist!$B$2:$B$400,"P*",Checklist!$F$2:$F$400,"N/A"))&" / "&COUNTIFS(Checklist!$A$2:$A$400,$A23,Checklist!$B$2:$B$400,"P*")) -> 0 / 8 | F23: =IF($A23="","",IF(Accounts!$K10="","Not held",Accounts!$K10)) -> Not held | G23: =IF(OR($A23="",Accounts!$N10="",Accounts!$O10=""),"",Accounts!$O10-Accounts!$N10) | H23: =IF($A23="","",COUNTIF(Deviations!$B$2:$B$151,$A23)) -> 0 | I23: =IF($A23="","",(AND(OR(Accounts!$J10="Onboarding",Accounts!$J10="Post-onboarding",Accounts!$J10="Done"),Accounts!$K10<>"Go"))*1+(COUNTIFS(Checklist!$A$2:$A$400,$A23,Checklist!$B$2:$B$400,"P*",Checklist!$F$2:$F$400,"Skipped")>0)*1+(AND(Accounts!$M10<>"",Accounts!$K10<>"Go"))*1+(AND(Accounts!$J10="Done",Accounts!$O10=""))*1) -> 0 | J23: =IF($A23="","",(AND(Accounts!$J10<>"Not started",Accounts!$I10=""))*1+(AND(OR(Accounts!$J10="Pre-onboarding",Accounts!$J10="Onboarding"),Accounts!$H10=""))*1+(IF(Accounts!$O10="",FALSE,AND(Accounts!$P10="",TODAY()-Accounts!$O10>2)))*1+(IF(Accounts!$U10="",FALSE,AND(Accounts!$U10<TODAY(),Accounts!$J10<>"Done")))*1+(IF(Accounts!$V10="",TRUE,TODAY()-Accounts!$V10>7))*1+(AND(Accounts!$S10="",Accounts!$J10<>"Done"))*1+(COUNTIFS(Checklist!$A$2:$A$400,$A23,Checklist!$K$2:$K$400,"*Evidence missing*")>0)*1) -> 2 | K23: =IF($A23="","",IF(I23>0,"RED",IF(J23>0,"AMBER","GREEN"))) -> AMBER | L23: =IF($A23="","",IF(AND(OR(Accounts!$J10="Onboarding",Accounts!$J10="Post-onboarding",Accounts!$J10="Done"),Accounts!$K10<>"Go"),"Onboarding started without a Go"&CHAR(10),"")&IF(COUNTIFS(Checklist!$A$2:$A$400,$A23,Checklist!$B$2:$B$400,"P*",Checklist!$F$2:$F$400,"Skipped")>0,"Pre-onboarding step skipped"&CHAR(10),"")&IF(AND(Accounts!$M10<>"",Accounts!$K10<>"Go"),"Date committed before the gate is green"&CHAR(10),"")&IF(AND(Accounts!$J10="Done",Accounts!$O10=""),"Marked Done before all scanners return data"&CHAR(10),"")&IF(AND(Accounts!$J10<>"Not started",Accounts!$I10=""),"No onboarding record linked"&CHAR(10),"")&IF(AND(OR(Accounts!$J10="Pre-onboarding",Accounts!$J10="Onboarding"),Accounts!$H10=""),"No named engineer"&CHAR(10),"")&IF(IF(Accounts!$O10="",FALSE,AND(Accounts!$P10="",TODAY()-Accounts!$O10>2)),"Retro overdue (48h rule)"&CHAR(10),"")&IF(IF(Accounts!$U10="",FALSE,AND(Accounts!$U10<TODAY(),Accounts!$J10<>"Done")),"Next action overdue"&CHAR(10),"")&IF(IF(Accounts!$V10="",TRUE,TODAY()-Accounts!$V10>7),"Not updated in 7+ days"&CHAR(10),"")&IF(AND(Accounts!$S10="",Accounts!$J10<>"Done"),"No next action set"&CHAR(10),"")&IF(COUNTIFS(Checklist!$A$2:$A$400,$A23,Checklist!$K$2:$K$400,"*Evidence missing*")>0,"Done step missing evidence"&CHAR(10),"")) -> Not updated in 7+ days No next action set | M23: =IF($A23="","",Accounts!$S10&"") | N23: =IF($A23="","",Accounts!$T10&"") | O23: =IF(OR($A23="",Accounts!$U10=""),"",Accounts!$U10)
A24: =IF(Accounts!$B11="","",Accounts!$B11) -> Mastercard | B24: =IF($A24="","",Accounts!$J11&"") -> Not started | C24: =IF($A24="","",Accounts!$F11&"") | D24: =IF($A24="","",Accounts!$G11&"") -> Khizar Karim | E24: =IF($A24="","",(COUNTIFS(Checklist!$A$2:$A$400,$A24,Checklist!$B$2:$B$400,"P*",Checklist!$F$2:$F$400,"Done")+COUNTIFS(Checklist!$A$2:$A$400,$A24,Checklist!$B$2:$B$400,"P*",Checklist!$F$2:$F$400,"N/A"))&" / "&COUNTIFS(Checklist!$A$2:$A$400,$A24,Checklist!$B$2:$B$400,"P*")) -> 0 / 0 | F24: =IF($A24="","",IF(Accounts!$K11="","Not held",Accounts!$K11)) -> Not held | G24: =IF(OR($A24="",Accounts!$N11="",Accounts!$O11=""),"",Accounts!$O11-Accounts!$N11) | H24: =IF($A24="","",COUNTIF(Deviations!$B$2:$B$151,$A24)) -> 0 | I24: =IF($A24="","",(AND(OR(Accounts!$J11="Onboarding",Accounts!$J11="Post-onboarding",Accounts!$J11="Done"),Accounts!$K11<>"Go"))*1+(COUNTIFS(Checklist!$A$2:$A$400,$A24,Checklist!$B$2:$B$400,"P*",Checklist!$F$2:$F$400,"Skipped")>0)*1+(AND(Accounts!$M11<>"",Accounts!$K11<>"Go"))*1+(AND(Accounts!$J11="Done",Accounts!$O11=""))*1) -> 0 | J24: =IF($A24="","",(AND(Accounts!$J11<>"Not started",Accounts!$I11=""))*1+(AND(OR(Accounts!$J11="Pre-onboarding",Accounts!$J11="Onboarding"),Accounts!$H11=""))*1+(IF(Accounts!$O11="",FALSE,AND(Accounts!$P11="",TODAY()-Accounts!$O11>2)))*1+(IF(Accounts!$U11="",FALSE,AND(Accounts!$U11<TODAY(),Accounts!$J11<>"Done")))*1+(IF(Accounts!$V11="",TRUE,TODAY()-Accounts!$V11>7))*1+(AND(Accounts!$S11="",Accounts!$J11<>"Done"))*1+(COUNTIFS(Checklist!$A$2:$A$400,$A24,Checklist!$K$2:$K$400,"*Evidence missing*")>0)*1) -> 2 | K24: =IF($A24="","",IF(I24>0,"RED",IF(J24>0,"AMBER","GREEN"))) -> AMBER | L24: =IF($A24="","",IF(AND(OR(Accounts!$J11="Onboarding",Accounts!$J11="Post-onboarding",Accounts!$J11="Done"),Accounts!$K11<>"Go"),"Onboarding started without a Go"&CHAR(10),"")&IF(COUNTIFS(Checklist!$A$2:$A$400,$A24,Checklist!$B$2:$B$400,"P*",Checklist!$F$2:$F$400,"Skipped")>0,"Pre-onboarding step skipped"&CHAR(10),"")&IF(AND(Accounts!$M11<>"",Accounts!$K11<>"Go"),"Date committed before the gate is green"&CHAR(10),"")&IF(AND(Accounts!$J11="Done",Accounts!$O11=""),"Marked Done before all scanners return data"&CHAR(10),"")&IF(AND(Accounts!$J11<>"Not started",Accounts!$I11=""),"No onboarding record linked"&CHAR(10),"")&IF(AND(OR(Accounts!$J11="Pre-onboarding",Accounts!$J11="Onboarding"),Accounts!$H11=""),"No named engineer"&CHAR(10),"")&IF(IF(Accounts!$O11="",FALSE,AND(Accounts!$P11="",TODAY()-Accounts!$O11>2)),"Retro overdue (48h rule)"&CHAR(10),"")&IF(IF(Accounts!$U11="",FALSE,AND(Accounts!$U11<TODAY(),Accounts!$J11<>"Done")),"Next action overdue"&CHAR(10),"")&IF(IF(Accounts!$V11="",TRUE,TODAY()-Accounts!$V11>7),"Not updated in 7+ days"&CHAR(10),"")&IF(AND(Accounts!$S11="",Accounts!$J11<>"Done"),"No next action set"&CHAR(10),"")&IF(COUNTIFS(Checklist!$A$2:$A$400,$A24,Checklist!$K$2:$K$400,"*Evidence missing*")>0,"Done step missing evidence"&CHAR(10),"")) -> Not updated in 7+ days No next action set | M24: =IF($A24="","",Accounts!$S11&"") | N24: =IF($A24="","",Accounts!$T11&"") | O24: =IF(OR($A24="",Accounts!$U11=""),"",Accounts!$U11)
A25: =IF(Accounts!$B12="","",Accounts!$B12) -> Thales | B25: =IF($A25="","",Accounts!$J12&"") -> Onboarding | C25: =IF($A25="","",Accounts!$F12&"") -> Ariel Nin | D25: =IF($A25="","",Accounts!$G12&"") -> Steve Briand | E25: =IF($A25="","",(COUNTIFS(Checklist!$A$2:$A$400,$A25,Checklist!$B$2:$B$400,"P*",Checklist!$F$2:$F$400,"Done")+COUNTIFS(Checklist!$A$2:$A$400,$A25,Checklist!$B$2:$B$400,"P*",Checklist!$F$2:$F$400,"N/A"))&" / "&COUNTIFS(Checklist!$A$2:$A$400,$A25,Checklist!$B$2:$B$400,"P*")) -> 0 / 8 | F25: =IF($A25="","",IF(Accounts!$K12="","Not held",Accounts!$K12)) -> Not held | G25: =IF(OR($A25="",Accounts!$N12="",Accounts!$O12=""),"",Accounts!$O12-Accounts!$N12) | H25: =IF($A25="","",COUNTIF(Deviations!$B$2:$B$151,$A25)) -> 0 | I25: =IF($A25="","",(AND(OR(Accounts!$J12="Onboarding",Accounts!$J12="Post-onboarding",Accounts!$J12="Done"),Accounts!$K12<>"Go"))*1+(COUNTIFS(Checklist!$A$2:$A$400,$A25,Checklist!$B$2:$B$400,"P*",Checklist!$F$2:$F$400,"Skipped")>0)*1+(AND(Accounts!$M12<>"",Accounts!$K12<>"Go"))*1+(AND(Accounts!$J12="Done",Accounts!$O12=""))*1) -> 2 | J25: =IF($A25="","",(AND(Accounts!$J12<>"Not started",Accounts!$I12=""))*1+(AND(OR(Accounts!$J12="Pre-onboarding",Accounts!$J12="Onboarding"),Accounts!$H12=""))*1+(IF(Accounts!$O12="",FALSE,AND(Accounts!$P12="",TODAY()-Accounts!$O12>2)))*1+(IF(Accounts!$U12="",FALSE,AND(Accounts!$U12<TODAY(),Accounts!$J12<>"Done")))*1+(IF(Accounts!$V12="",TRUE,TODAY()-Accounts!$V12>7))*1+(AND(Accounts!$S12="",Accounts!$J12<>"Done"))*1+(COUNTIFS(Checklist!$A$2:$A$400,$A25,Checklist!$K$2:$K$400,"*Evidence missing*")>0)*1) -> 4 | K25: =IF($A25="","",IF(I25>0,"RED",IF(J25>0,"AMBER","GREEN"))) -> RED | L25: =IF($A25="","",IF(AND(OR(Accounts!$J12="Onboarding",Accounts!$J12="Post-onboarding",Accounts!$J12="Done"),Accounts!$K12<>"Go"),"Onboarding started without a Go"&CHAR(10),"")&IF(COUNTIFS(Checklist!$A$2:$A$400,$A25,Checklist!$B$2:$B$400,"P*",Checklist!$F$2:$F$400,"Skipped")>0,"Pre-onboarding step skipped"&CHAR(10),"")&IF(AND(Accounts!$M12<>"",Accounts!$K12<>"Go"),"Date committed before the gate is green"&CHAR(10),"")&IF(AND(Accounts!$J12="Done",Accounts!$O12=""),"Marked Done before all scanners return data"&CHAR(10),"")&IF(AND(Accounts!$J12<>"Not started",Accounts!$I12=""),"No onboarding record linked"&CHAR(10),"")&IF(AND(OR(Accounts!$J12="Pre-onboarding",Accounts!$J12="Onboarding"),Accounts!$H12=""),"No named engineer"&CHAR(10),"")&IF(IF(Accounts!$O12="",FALSE,AND(Accounts!$P12="",TODAY()-Accounts!$O12>2)),"Retro overdue (48h rule)"&CHAR(10),"")&IF(IF(Accounts!$U12="",FALSE,AND(Accounts!$U12<TODAY(),Accounts!$J12<>"Done")),"Next action overdue"&CHAR(10),"")&IF(IF(Accounts!$V12="",TRUE,TODAY()-Accounts!$V12>7),"Not updated in 7+ days"&CHAR(10),"")&IF(AND(Accounts!$S12="",Accounts!$J12<>"Done"),"No next action set"&CHAR(10),"")&IF(COUNTIFS(Checklist!$A$2:$A$400,$A25,Checklist!$K$2:$K$400,"*Evidence missing*")>0,"Done step missing evidence"&CHAR(10),"")) -> Onboarding started without a Go Date committed before the gate is green No onboarding record linked No named engineer Not updated in 7+ days No next action set | M25: =IF($A25="","",Accounts!$S12&"") | N25: =IF($A25="","",Accounts!$T12&"") | O25: =IF(OR($A25="",Accounts!$U12=""),"",Accounts!$U12)
A26: =IF(Accounts!$B13="","",Accounts!$B13) -> Verizon | B26: =IF($A26="","",Accounts!$J13&"") -> Post-onboarding | C26: =IF($A26="","",Accounts!$F13&"") | D26: =IF($A26="","",Accounts!$G13&"") -> Farooq Abrahem | E26: =IF($A26="","",(COUNTIFS(Checklist!$A$2:$A$400,$A26,Checklist!$B$2:$B$400,"P*",Checklist!$F$2:$F$400,"Done")+COUNTIFS(Checklist!$A$2:$A$400,$A26,Checklist!$B$2:$B$400,"P*",Checklist!$F$2:$F$400,"N/A"))&" / "&COUNTIFS(Checklist!$A$2:$A$400,$A26,Checklist!$B$2:$B$400,"P*")) -> 0 / 0 | F26: =IF($A26="","",IF(Accounts!$K13="","Not held",Accounts!$K13)) -> Not held | G26: =IF(OR($A26="",Accounts!$N13="",Accounts!$O13=""),"",Accounts!$O13-Accounts!$N13) | H26: =IF($A26="","",COUNTIF(Deviations!$B$2:$B$151,$A26)) -> 0 | I26: =IF($A26="","",(AND(OR(Accounts!$J13="Onboarding",Accounts!$J13="Post-onboarding",Accounts!$J13="Done"),Accounts!$K13<>"Go"))*1+(COUNTIFS(Checklist!$A$2:$A$400,$A26,Checklist!$B$2:$B$400,"P*",Checklist!$F$2:$F$400,"Skipped")>0)*1+(AND(Accounts!$M13<>"",Accounts!$K13<>"Go"))*1+(AND(Accounts!$J13="Done",Accounts!$O13=""))*1) -> 1 | J26: =IF($A26="","",(AND(Accounts!$J13<>"Not started",Accounts!$I13=""))*1+(AND(OR(Accounts!$J13="Pre-onboarding",Accounts!$J13="Onboarding"),Accounts!$H13=""))*1+(IF(Accounts!$O13="",FALSE,AND(Accounts!$P13="",TODAY()-Accounts!$O13>2)))*1+(IF(Accounts!$U13="",FALSE,AND(Accounts!$U13<TODAY(),Accounts!$J13<>"Done")))*1+(IF(Accounts!$V13="",TRUE,TODAY()-Accounts!$V13>7))*1+(AND(Accounts!$S13="",Accounts!$J13<>"Done"))*1+(COUNTIFS(Checklist!$A$2:$A$400,$A26,Checklist!$K$2:$K$400,"*Evidence missing*")>0)*1) -> 3 | K26: =IF($A26="","",IF(I26>0,"RED",IF(J26>0,"AMBER","GREEN"))) -> RED | L26: =IF($A26="","",IF(AND(OR(Accounts!$J13="Onboarding",Accounts!$J13="Post-onboarding",Accounts!$J13="Done"),Accounts!$K13<>"Go"),"Onboarding started without a Go"&CHAR(10),"")&IF(COUNTIFS(Checklist!$A$2:$A$400,$A26,Checklist!$B$2:$B$400,"P*",Checklist!$F$2:$F$400,"Skipped")>0,"Pre-onboarding step skipped"&CHAR(10),"")&IF(AND(Accounts!$M13<>"",Accounts!$K13<>"Go"),"Date committed before the gate is green"&CHAR(10),"")&IF(AND(Accounts!$J13="Done",Accounts!$O13=""),"Marked Done before all scanners return data"&CHAR(10),"")&IF(AND(Accounts!$J13<>"Not started",Accounts!$I13=""),"No onboarding record linked"&CHAR(10),"")&IF(AND(OR(Accounts!$J13="Pre-onboarding",Accounts!$J13="Onboarding"),Accounts!$H13=""),"No named engineer"&CHAR(10),"")&IF(IF(Accounts!$O13="",FALSE,AND(Accounts!$P13="",TODAY()-Accounts!$O13>2)),"Retro overdue (48h rule)"&CHAR(10),"")&IF(IF(Accounts!$U13="",FALSE,AND(Accounts!$U13<TODAY(),Accounts!$J13<>"Done")),"Next action overdue"&CHAR(10),"")&IF(IF(Accounts!$V13="",TRUE,TODAY()-Accounts!$V13>7),"Not updated in 7+ days"&CHAR(10),"")&IF(AND(Accounts!$S13="",Accounts!$J13<>"Done"),"No next action set"&CHAR(10),"")&IF(COUNTIFS(Checklist!$A$2:$A$400,$A26,Checklist!$K$2:$K$400,"*Evidence missing*")>0,"Done step missing evidence"&CHAR(10),"")) -> Onboarding started without a Go No onboarding record linked Not updated in 7+ days No next action set | M26: =IF($A26="","",Accounts!$S13&"") | N26: =IF($A26="","",Accounts!$T13&"") | O26: =IF(OR($A26="",Accounts!$U13=""),"",Accounts!$U13)
A27: =IF(Accounts!$B14="","",Accounts!$B14) -> Early Warning Services LLC | B27: =IF($A27="","",Accounts!$J14&"") -> Onboarding | C27: =IF($A27="","",Accounts!$F14&"") | D27: =IF($A27="","",Accounts!$G14&"") -> Lindsey Smith | E27: =IF($A27="","",(COUNTIFS(Checklist!$A$2:$A$400,$A27,Checklist!$B$2:$B$400,"P*",Checklist!$F$2:$F$400,"Done")+COUNTIFS(Checklist!$A$2:$A$400,$A27,Checklist!$B$2:$B$400,"P*",Checklist!$F$2:$F$400,"N/A"))&" / "&COUNTIFS(Checklist!$A$2:$A$400,$A27,Checklist!$B$2:$B$400,"P*")) -> 0 / 8 | F27: =IF($A27="","",IF(Accounts!$K14="","Not held",Accounts!$K14)) -> Not held | G27: =IF(OR($A27="",Accounts!$N14="",Accounts!$O14=""),"",Accounts!$O14-Accounts!$N14) | H27: =IF($A27="","",COUNTIF(Deviations!$B$2:$B$151,$A27)) -> 0 | I27: =IF($A27="","",(AND(OR(Accounts!$J14="Onboarding",Accounts!$J14="Post-onboarding",Accounts!$J14="Done"),Accounts!$K14<>"Go"))*1+(COUNTIFS(Checklist!$A$2:$A$400,$A27,Checklist!$B$2:$B$400,"P*",Checklist!$F$2:$F$400,"Skipped")>0)*1+(AND(Accounts!$M14<>"",Accounts!$K14<>"Go"))*1+(AND(Accounts!$J14="Done",Accounts!$O14=""))*1) -> 1 | J27: =IF($A27="","",(AND(Accounts!$J14<>"Not started",Accounts!$I14=""))*1+(AND(OR(Accounts!$J14="Pre-onboarding",Accounts!$J14="Onboarding"),Accounts!$H14=""))*1+(IF(Accounts!$O14="",FALSE,AND(Accounts!$P14="",TODAY()-Accounts!$O14>2)))*1+(IF(Accounts!$U14="",FALSE,AND(Accounts!$U14<TODAY(),Accounts!$J14<>"Done")))*1+(IF(Accounts!$V14="",TRUE,TODAY()-Accounts!$V14>7))*1+(AND(Accounts!$S14="",Accounts!$J14<>"Done"))*1+(COUNTIFS(Checklist!$A$2:$A$400,$A27,Checklist!$K$2:$K$400,"*Evidence missing*")>0)*1) -> 4 | K27: =IF($A27="","",IF(I27>0,"RED",IF(J27>0,"AMBER","GREEN"))) -> RED | L27: =IF($A27="","",IF(AND(OR(Accounts!$J14="Onboarding",Accounts!$J14="Post-onboarding",Accounts!$J14="Done"),Accounts!$K14<>"Go"),"Onboarding started without a Go"&CHAR(10),"")&IF(COUNTIFS(Checklist!$A$2:$A$400,$A27,Checklist!$B$2:$B$400,"P*",Checklist!$F$2:$F$400,"Skipped")>0,"Pre-onboarding step skipped"&CHAR(10),"")&IF(AND(Accounts!$M14<>"",Accounts!$K14<>"Go"),"Date committed before the gate is green"&CHAR(10),"")&IF(AND(Accounts!$J14="Done",Accounts!$O14=""),"Marked Done before all scanners return data"&CHAR(10),"")&IF(AND(Accounts!$J14<>"Not started",Accounts!$I14=""),"No onboarding record linked"&CHAR(10),"")&IF(AND(OR(Accounts!$J14="Pre-onboarding",Accounts!$J14="Onboarding"),Accounts!$H14=""),"No named engineer"&CHAR(10),"")&IF(IF(Accounts!$O14="",FALSE,AND(Accounts!$P14="",TODAY()-Accounts!$O14>2)),"Retro overdue (48h rule)"&CHAR(10),"")&IF(IF(Accounts!$U14="",FALSE,AND(Accounts!$U14<TODAY(),Accounts!$J14<>"Done")),"Next action overdue"&CHAR(10),"")&IF(IF(Accounts!$V14="",TRUE,TODAY()-Accounts!$V14>7),"Not updated in 7+ days"&CHAR(10),"")&IF(AND(Accounts!$S14="",Accounts!$J14<>"Done"),"No next action set"&CHAR(10),"")&IF(COUNTIFS(Checklist!$A$2:$A$400,$A27,Checklist!$K$2:$K$400,"*Evidence missing*")>0,"Done step missing evidence"&CHAR(10),"")) -> Onboarding started without a Go No onboarding record linked No named engineer Not updated in 7+ days No next action set | M27: =IF($A27="","",Accounts!$S14&"") | N27: =IF($A27="","",Accounts!$T14&"") | O27: =IF(OR($A27="",Accounts!$U14=""),"",Accounts!$U14)

Sheet Accounts
A1: # | B1: Account | C1: Motion | D1: Prior onboarding issues | E1: Cloud(s) | F1: PS consultant | G1: TSE | H1: Named engineer | I1: Onboarding Record link | J1: Stage | K1: Go / No Go | L1: Go / No Go date | M1: Committed onboarding date | N1: Terraform apply date | O1: All scanners returning data successfully (date) | P1: Retro date | Q1: CS handover date | R1: Open blocker | S1: Next action | T1: Next action owner | U1: Next action due | V1: Last updated | W1: Notes
A2: 1 | B2: Zoom Video | C2: Upgrade | D2: N | E2: AWS, OCI, GCP, Azure | F2: Matthew Dombrowski | G2: Z Yu | J2: Onboarding | M2: TBD | R2: Issues with asset count in Cortex. Currently being looked at by engineering. | S2: Once issues are resolved, we can continue onboarding GCP and Azure (if customer wants to in migration) | T2: Matt-PS Mark - EE Zoom - Cloud Ops | U2: TBD | V2: 46288
A3: 2 | B3: Broadcom | C3: Upgrade | D3: N | E3: Azure, GCP, AWS | F3: Stephen Lovett | G3: Z Yu | I3: OAE - Broadcom - Tracker | J3: Onboarding | K3: Not held | S3: Pending customer's internal ticket to have cloud admin review outpost terraform files and apply. | V3: 46288
A4: 3 | B4: Telecom Guatemala | C4: Net new | D4: Y | E4: Azure | F4: Ariel Nin | G4: Fabio Cezar (DC) | I4: OAE - Telecomunicaciones De Guatemala - Tracker | J4: Done | M4: 46289 | N4: 09/24 Reapplied on 09/30 | O4: 46300 | Q4: N/A | R4: N/A | S4: Continue the Cortex Cloud CSPM deployment | T4: Ariel Nin - Professional Services | U4: 10/05 onwards | V4: 46303 | W4: N/A
A5: 4 | B5: FIS Global | C5: Net new | D5: Y | E5: Azure, GCP, AWS, OCI | F5: Stephen Lovett | G5: Harold Moore (DC) | I5: OAE - FIS Global - Tracker | J5: Not started | S5: Customer has onboarded all their Cloud Providers however seeing errors and warnings. Customer has indicated expanding security capabilities and pivot towards outposts. | V5: 46288
A6: 5 | B6: Fidelity | C6: Upgrade | D6: Y | E6: Azure | F6: Stephen Lovett | G6: Ravi Badana | I6: OAE - FnF - Tracker | J6: Pre-onboarding | S6: Customer is conducting POV | V6: 46288
A7: 6 | B7: DOI | C7: Upgrade | D7: Y | E7: Azure, GCP, AWS | F7: Stephen Lovett | I7: OAE - DOI - Tracker | J7: Not started | S7: On hold | V7: 46288
A8: 7 | B8: Marriott | C8: Upgrade | D8: N | E8: AWS, Azure, Alibaba, GCP, OCI | F8: Bliss Jourdan | G8: Khizar Karim | I8: OAE - Marriott - Tracker | J8: Onboarding | M8: Next Sprint. Within 2 weeks. | R8: Want updates to the AWS CFT. Want to remove the lamdba function and connect manually. | V8: 46303
A9: 8 | B9: Honeywell International | C9: Upgrade | D9: N | E9: AWS, Azure, Alibaba, GCP, OCI | F9: Kirk Preston | I9: Honeywell Onboarding + Tracker | J9: Onboarding | M9: ETA, Likely 10/27 or 11/3 (contd) | N9: AWS Commercial: 9/17/26, GCP Commercial: 2026-10-15 | O9: AWS Commerical: 2026-09-24 | Q9: N/A | R9: Customer is evaluating compliance reporting parity before onboarding more accounts/CSPs. This could delay onboarding. | S9: Download CSP templates for internal review proactively. | T9: TBD | U9: TBD | V9: 46314
A10: 9 | B10: Salesforce - ESS org | C10: Upgrade | D10: N | F10: Bliss Jourdan | G10: Khizar Karim | J10: Not started | V10: 46288
A11: 10 | B11: Mastercard | C11: Upgrade | D11: Unknown | G11: Khizar Karim | J11: Not started | V11: 46288
A12: 11 | B12: Thales | C12: Upgrade | D12: Y | E12: AWS,GCP | F12: Ariel Nin | G12: Steve Briand | J12: Onboarding | K12: Not held | M12: 46294 | R12: Csutomer is evaluating Cortex Cloud vs Wiz and has experienced various Errors and Warnings during onboarding.
A13: 12 | B13: Verizon | C13: Upgrade | D13: Y | E13: AWS | G13: Farooq Abrahem | J13: Post-onboarding | N13: 46293 | R13: We have onboarded Verizon to AWS outpost. They are evaluating Wiz too. | W13: Over the past week, we have been working through a series of AWS governance blockers with Verizon to deploy the Cortex Cloud Outpost, starting with a Duplicate tag key 'Name' error that was resolved by removing the 'Name' tag from the Terraform variables. After that, scans failed with InvalidSnapshot.NotFound because Verizon's internal auto-tagging Lambda (VzGov-Tagger) was aggressively deleting our temporary snapshots for lacking mandatory corporate tags, which the customer has since mitigated by updating their Lambda configuration to whitelist the Cortex role. Today, however, we are seeing new failures—specifically Workload status not found and InvalidVolume.NotFound (likely due to Cortex targeting ephemeral volumes that their auto-scaler already terminated). Because the customer is experiencing severe migration fatigue and Wiz is actively courting them, we cannot ask Verizon to pull more CloudTrail logs. We urgently need backend engineering to review our internal telemetry for the Outpost proxy connection and fleet logs to determine why the scanner workloads are failing to launch or report back.
A14: 13 | B14: Early Warning Services LLC | C14: Upgrade | D14: Y | E14: AWS, Azure | G14: Lindsey Smith | J14: Onboarding | R14: EWS are experiencing very low resource accounts indicating issues with onboarding | W14: AWS is their largest cloud provider and primary focus. EWS have tried to onboard on their own, with multiple tries, but not full success.
A15: 14
A16: 15
A17: 16
A18: 17
A19: 18
A20: 19
A21: 20

Sheet Checklist
A1: Account | B1: Step ID (P = Pre, D = During, V = Post) | C1: Step (full text and exit criterion in Steps tab) | D1: Owner role | E1: Named owner | F1: Status | G1: Date done | H1: Evidence / asset link | I1: Evidence required | J1: Notes | K1: Row flag
A2: Zoom Video | B2: P1 | C2: Onboarding Record created and linked | D2: TSE | E2: {=IF($A2="","",IFERROR(IF($D2="TSE",INDEX(Accounts!$G$2:$G$21,MATCH($A2,Accounts!$B$2:$B$21,0))&"",IF($D2="PS",INDEX(Accounts!$F$2:$F$21,MATCH($A2,Accounts!$B$2:$B$21,0))&"",IF($D2="Named engineer",INDEX(Accounts!$I$2:$I$21,MATCH($A2,Accounts!$B$2:$B$21,0))&"",IF($D2="TSE + PS",IF(INDEX(Accounts!$G$2:$G$21,MATCH($A2,Accounts!$B$2:$B$21,0))&""="","(no TSE)",INDEX(Accounts!$G$2:$G$21,MATCH($A2,Accounts!$B$2:$B$21,0))&"")&" / "&IF(INDEX(Accounts!$F$2:$F$21,MATCH($A2,Accounts!$B$2:$B$21,0))&""="","(no PS)",INDEX(Accounts!$F$2:$F$21,MATCH($A2,Accounts!$B$2:$B$21,0))&""),"")))),""))} -> Z Yu | F2: Not started | I2: Y | K2: =IF(F2="Done",IF(AND(I2="Y",H2=""),"Evidence missing ","")&IF(G2="","Date missing ",""),"")&IF(E2="","Owner missing ","")&IF(F2="Skipped","Skipped","")
A3: Zoom Video | B3: P2 | C3: Technical assessment | D3: TSE | E3: {=IF($A3="","",IFERROR(IF($D3="TSE",INDEX(Accounts!$G$2:$G$21,MATCH($A3,Accounts!$B$2:$B$21,0))&"",IF($D3="PS",INDEX(Accounts!$F$2:$F$21,MATCH($A3,Accounts!$B$2:$B$21,0))&"",IF($D3="Named engineer",INDEX(Accounts!$I$2:$I$21,MATCH($A3,Accounts!$B$2:$B$21,0))&"",IF($D3="TSE + PS",IF(INDEX(Accounts!$G$2:$G$21,MATCH($A3,Accounts!$B$2:$B$21,0))&""="","(no TSE)",INDEX(Accounts!$G$2:$G$21,MATCH($A3,Accounts!$B$2:$B$21,0))&"")&" / "&IF(INDEX(Accounts!$F$2:$F$21,MATCH($A3,Accounts!$B$2:$B$21,0))&""="","(no PS)",INDEX(Accounts!$F$2:$F$21,MATCH($A3,Accounts!$B$2:$B$21,0))&""),"")))),""))} -> Z Yu | F3: Not started | I3: Y | K3: =IF(F3="Done",IF(AND(I3="Y",H3=""),"Evidence missing ","")&IF(G3="","Date missing ",""),"")&IF(E3="","Owner missing ","")&IF(F3="Skipped","Skipped","")
A4: Zoom Video | B4: P3 | C4: Permission pre-flight on named admins | D4: TSE | E4: {=IF($A4="","",IFERROR(IF($D4="TSE",INDEX(Accounts!$G$2:$G$21,MATCH($A4,Accounts!$B$2:$B$21,0))&"",IF($D4="PS",INDEX(Accounts!$F$2:$F$21,MATCH($A4,Accounts!$B$2:$B$21,0))&"",IF($D4="Named engineer",INDEX(Accounts!$I$2:$I$21,MATCH($A4,Accounts!$B$2:$B$21,0))&"",IF($D4="TSE + PS",IF(INDEX(Accounts!$G$2:$G$21,MATCH($A4,Accounts!$B$2:$B$21,0))&""="","(no TSE)",INDEX(Accounts!$G$2:$G$21,MATCH($A4,Accounts!$B$2:$B$21,0))&"")&" / "&IF(INDEX(Accounts!$F$2:$F$21,MATCH($A4,Accounts!$B$2:$B$21,0))&""="","(no PS)",INDEX(Accounts!$F$2:$F$21,MATCH($A4,Accounts!$B$2:$B$21,0))&""),"")))),""))} -> Z Yu | F4: Not started | I4: Y | K4: =IF(F4="Done",IF(AND(I4="Y",H4=""),"Evidence missing ","")&IF(G4="","Date missing ",""),"")&IF(E4="","Owner missing ","")&IF(F4="Skipped","Skipped","")
A5: Zoom Video | B5: P4 | C5: Engineering review; pre-facto noise suppression | D5: Named engineer | E5: {=IF($A5="","",IFERROR(IF($D5="TSE",INDEX(Accounts!$G$2:$G$21,MATCH($A5,Accounts!$B$2:$B$21,0))&"",IF($D5="PS",INDEX(Accounts!$F$2:$F$21,MATCH($A5,Accounts!$B$2:$B$21,0))&"",IF($D5="Named engineer",INDEX(Accounts!$I$2:$I$21,MATCH($A5,Accounts!$B$2:$B$21,0))&"",IF($D5="TSE + PS",IF(INDEX(Accounts!$G$2:$G$21,MATCH($A5,Accounts!$B$2:$B$21,0))&""="","(no TSE)",INDEX(Accounts!$G$2:$G$21,MATCH($A5,Accounts!$B$2:$B$21,0))&"")&" / "&IF(INDEX(Accounts!$F$2:$F$21,MATCH($A5,Accounts!$B$2:$B$21,0))&""="","(no PS)",INDEX(Accounts!$F$2:$F$21,MATCH($A5,Accounts!$B$2:$B$21,0))&""),"")))),""))} | F5: Not started | I5: Y | K5: =IF(F5="Done",IF(AND(I5="Y",H5=""),"Evidence missing ","")&IF(G5="","Date missing ",""),"")&IF(E5="","Owner missing ","")&IF(F5="Skipped","Skipped","") -> Owner missing
A6: Zoom Video | B6: P5 | C6: Branch decisions recorded | D6: TSE | E6: {=IF($A6="","",IFERROR(IF($D6="TSE",INDEX(Accounts!$G$2:$G$21,MATCH($A6,Accounts!$B$2:$B$21,0))&"",IF($D6="PS",INDEX(Accounts!$F$2:$F$21,MATCH($A6,Accounts!$B$2:$B$21,0))&"",IF($D6="Named engineer",INDEX(Accounts!$I$2:$I$21,MATCH($A6,Accounts!$B$2:$B$21,0))&"",IF($D6="TSE + PS",IF(INDEX(Accounts!$G$2:$G$21,MATCH($A6,Accounts!$B$2:$B$21,0))&""="","(no TSE)",INDEX(Accounts!$G$2:$G$21,MATCH($A6,Accounts!$B$2:$B$21,0))&"")&" / "&IF(INDEX(Accounts!$F$2:$F$21,MATCH($A6,Accounts!$B$2:$B$21,0))&""="","(no PS)",INDEX(Accounts!$F$2:$F$21,MATCH($A6,Accounts!$B$2:$B$21,0))&""),"")))),""))} -> Z Yu | F6: Not started | I6: Y | K6: =IF(F6="Done",IF(AND(I6="Y",H6=""),"Evidence missing ","")&IF(G6="","Date missing ",""),"")&IF(E6="","Owner missing ","")&IF(F6="Skipped","Skipped","")
A7: Zoom Video | B7: P6 | C7: Wizard and branches workshop (TSE, TPE, PS) | D7: TSE | E7: {=IF($A7="","",IFERROR(IF($D7="TSE",INDEX(Accounts!$G$2:$G$21,MATCH($A7,Accounts!$B$2:$B$21,0))&"",IF($D7="PS",INDEX(Accounts!$F$2:$F$21,MATCH($A7,Accounts!$B$2:$B$21,0))&"",IF($D7="Named engineer",INDEX(Accounts!$I$2:$I$21,MATCH($A7,Accounts!$B$2:$B$21,0))&"",IF($D7="TSE + PS",IF(INDEX(Accounts!$G$2:$G$21,MATCH($A7,Accounts!$B$2:$B$21,0))&""="","(no TSE)",INDEX(Accounts!$G$2:$G$21,MATCH($A7,Accounts!$B$2:$B$21,0))&"")&" / "&IF(INDEX(Accounts!$F$2:$F$21,MATCH($A7,Accounts!$B$2:$B$21,0))&""="","(no PS)",INDEX(Accounts!$F$2:$F$21,MATCH($A7,Accounts!$B$2:$B$21,0))&""),"")))),""))} -> Z Yu | F7: Not started | I7: N | K7: =IF(F7="Done",IF(AND(I7="Y",H7=""),"Evidence missing ","")&IF(G7="","Date missing ",""),"")&IF(E7="","Owner missing ","")&IF(F7="Skipped","Skipped","")
