Workbook

Sheet How to use
B1: Cortex Cloud upgrade: field assessment tracker
B3: What this tracker answers for each account
B4: 1) Which technical blockers the customer has confirmed. 2) Which of those have no committed release date. 3) Which release clears the account, and the expected start date.
B6: How to fill it in
B7: 1. Accounts tab: one row per account. Fill the white columns. Set Assessment status to Complete only when every relevant gap has been validated with the customer.
B8: 2. Blocker log tab: one row per gap discussed with the customer. Pick the account and gap from the dropdowns; release, default view and PM owner fill in automatically. This is for Roadmap blocking items only (Parity and Top 100 Account Feature Requests)
B9: 3. Set Customer outcome: Hard blocker, Workaround accepted, Not needed or Unknown. For a blocker that is not on the gap list, pick 'Other (not on gap list)' and describe it.
B10: 4. Record whether telemetry matched what the customer told you. These corrections improve telemetry for the next wave of accounts.
B11: 5. Playbook feedback tab: anything we should change in the runbook, telemetry or product.
B13: How the readiness bucket is set (automatic)
B14: Ready now: no validated hard blockers. Otherwise the latest planned release among the account's hard blockers sets the bucket.
B15: No date: at least one hard blocker has No date, TBC, Not planned or Unknown. These rows show Escalate = Yes in the Blocker log; raise them with the PM owner.
... B21: The full approach is in the TSE Field Assessment Guide.

Sheet Summary
A1: Field assessment summary
A2: All figures update from the Accounts and Blocker log tabs. Grey cells are formulas; do not type over them.
A4: Coverage
A5: Accounts in scope | B5: =COUNTA(Accounts!$B:$B) -> 1368
A6: Assessments complete | B6: =COUNTIF(Accounts!$K$2:$K$161,"Complete") -> 15
A7: % complete | B7: =IF(B5=0,0,B6/B5) -> 0.010964912
A9: Readiness buckets (completed assessments)
A10: Bucket | B10: # accounts | C10: ARR ($M) | D10: % of complete
A11: Ready now | B11: =COUNTIF(Accounts!$Q:$Q,$A11) -> 15 | C11: =SUMIFS(Accounts!$H:$H,Accounts!$Q:$Q,$A11) -> 22194564 | D11: =IF($B$6=0,0,B11/$B$6) -> 1
A12: After October release | B12: =COUNTIF(Accounts!$Q:$Q,$A12) -> 0 | C12: =SUMIFS(Accounts!$H:$H,Accounts!$Q:$Q,$A12) -> 0 | D12: =IF($B$6=0,0,B12/$B$6) -> 0
A13: After January release | B13: =COUNTIF(Accounts!$Q:$Q,$A13) -> 0 | C13: =SUMIFS(Accounts!$H:$H,Accounts!$Q:$Q,$A13) -> 0 | D13: =IF($B$6=0,0,B13/$B$6) -> 0
A14: After April release or later | B14: =COUNTIF(Accounts!$Q:$Q,$A14) -> 0 | C14: =SUMIFS(Accounts!$H:$H,Accounts!$Q:$Q,$A14) -> 0 | D14: =IF($B$6=0,0,B14/$B$6) -> 0
A15: No date | B15: =COUNTIF(Accounts!$Q:$Q,$A15) -> 0 | C15: =SUMIFS(Accounts!$H:$H,Accounts!$Q:$Q,$A15) -> 0 | D15: =IF($B$6=0,0,B15/$B$6) -> 0
A16: Assessment pending | B16: =COUNTIF(Accounts!$Q:$Q,$A16) -> 1351 | C16: =SUMIFS(Accounts!$H:$H,Accounts!$Q:$Q,$A16) -> 265893694
A18: Blockers
A19: Validated hard blockers (all accounts) | B19: =COUNTIF('Blocker log'!$G:$G,"Hard blocker") -> 12
A20: Hard blockers with no committed date | B20: =COUNTIF('Blocker log'!$M:$M,"Yes") -> 0
A21: Accounts with a no-date hard blocker | B21: =COUNTIF(Accounts!$O$2:$O$161,">0") -> 0
A22: Workarounds accepted | B22: =COUNTIF('Blocker log'!$G:$G,"Workaround accepted") -> 5
A23: Blockers not on the gap list | B23: =COUNTIFS('Blocker log'!$B:$B,"Other (not on gap list)",'Blocker log'!$G:$G,"Hard blocker") -> 0
A24: Telemetry mismatches found | B24: =COUNTIF('Blocker log'!$J:$J,"No, *") -> 2
A26: Most common hard blockers: sort the Gap reference tab by its last column.

Sheet Accounts
A1: Account iD | B1: Account | C1: Tier | D1: Theatre | G1: Upgrade status | H1: ARR ($M) | I1: TSE | J1: Companion (ride-along) | K1: Assessment status | L1: Assessment date | M1: # gaps validated | N1: # hard blockers | O1: # hard blockers with no date | P1: Latest release rank | Q1: Readiness bucket | R1: Expected start date | S1: Next step | T1: Escalation reason | U1: Notes
A2: 0017000000qySjdAAE | B2: Cognizant Technology Solutions Corporation | C2: Tier 1 | D2: AMER | E2: AMER Strategic East | F2: AMER Strategic East SI/SP | G2: Cohort 1: Upgrades in progress | H2: 3387281 | I2: Alan Simpkins | K2: Complete | L2: 46315 | M2: =IF($B2="","",COUNTIFS('Blocker log'!$A:$A,$B2,'Blocker log'!$G:$G,"<>")) -> 0 | N2: =IF($B2="","",COUNTIFS('Blocker log'!$A:$A,$B2,'Blocker log'!$G:$G,"Hard blocker")) -> 0 | O2: =IF($B2="","",COUNTIFS('Blocker log'!$A:$A,$B2,'Blocker log'!$G:$G,"Hard blocker",'Blocker log'!$L:$L,9)) -> 0 | P2: =IF($B2="","",MAXIFS('Blocker log'!$L:$L,'Blocker log'!$A:$A,$B2,'Blocker log'!$G:$G,"Hard blocker")) -> 0 | Q2: =IF($B2="","",IF($K2<>"Complete","Assessment pending",IF($N2=0,"Ready now",VLOOKUP($P2,Lists!$D$2:$E$5,2,FALSE)))) -> Ready now
A3: 0017000000WRcO6AAL | B3: HARTFORD FIRE INSURANCE COMPANY | C3: Tier 2 | D3: AMER | E3: AMER Strategic East | F3: AMER Strategic East Northeast | G3: Cohort 1: Upgrades in progress | H3: 333600 | I3: Alan Simpkins | K3: Pending | M3: =IF($B3="","",COUNTIFS('Blocker log'!$A:$A,$B3,'Blocker log'!$G:$G,"<>")) -> 0 | N3: =IF($B3="","",COUNTIFS('Blocker log'!$A:$A,$B3,'Blocker log'!$G:$G,"Hard blocker")) -> 0 | O3: =IF($B3="","",COUNTIFS('Blocker log'!$A:$A,$B3,'Blocker log'!$G:$G,"Hard blocker",'Blocker log'!$L:$L,9)) -> 0 | P3: =IF($B3="","",MAXIFS('Blocker log'!$L:$L,'Blocker log'!$A:$A,$B3,'Blocker log'!$G:$G,"Hard blocker")) -> 0 | Q3: =IF($B3="","",IF($K3<>"Complete","Assessment pending",IF($N3=0,"Ready now",VLOOKUP($P3,Lists!$D$2:$E$5,2,FALSE)))) -> Assessment pending
A4: 0017000000LKb1aAAD | B4: Connection | C4: Tier 2 | D4: AMER | E4: AMER Acquisition | F4: AMER Acquisition | G4: Cohort 1: Upgrades in progress | H4: 33192 | I4: Alan Simpkins | K4: Pending | M4: =IF($B4="","",COUNTIFS('Blocker log'!$A:$A,$B4,'Blocker log'!$G:$G,"<>")) -> 0 | N4: =IF($B4="","",COUNTIFS('Blocker log'!$A:$A,$B4,'Blocker log'!$G:$G,"Hard blocker")) -> 0 | O4: =IF($B4="","",COUNTIFS('Blocker log'!$A:$A,$B4,'Blocker log'!$G:$G,"Hard blocker",'Blocker log'!$L:$L,9)) -> 0 | P4: =IF($B4="","",MAXIFS('Blocker log'!$L:$L,'Blocker log'!$A:$A,$B4,'Blocker log'!$G:$G,"Hard blocker")) -> 0 | Q4: =IF($B4="","",IF($K4<>"Complete","Assessment pending",IF($N4=0,"Ready now",VLOOKUP($P4,Lists!$D$2:$E$5,2,FALSE)))) -> Assessment pending
A5: 0017000000Wc7W0AAJ | B5: ISO New England Inc. | C5: Tier 2 | D5: AMER | E5: AMER Commercial | F5: Select East | G5: Cohort 1: Upgrades in progress | H5: 123584 | I5: Alan Simpkins | K5: Pending | M5: =IF($B5="","",COUNTIFS('Blocker log'!$A:$A,$B5,'Blocker log'!$G:$G,"<>")) -> 0 | N5: =IF($B5="","",COUNTIFS('Blocker log'!$A:$A,$B5,'Blocker log'!$G:$G,"Hard blocker")) -> 0 | O5: =IF($B5="","",COUNTIFS('Blocker log'!$A:$A,$B5,'Blocker log'!$G:$G,"Hard blocker",'Blocker log'!$L:$L,9)) -> 0 | P5: =IF($B5="","",MAXIFS('Blocker log'!$L:$L,'Blocker log'!$A:$A,$B5,'Blocker log'!$G:$G,"Hard blocker")) -> 0 | Q5: =IF($B5="","",IF($K5<>"Complete","Assessment pending",IF($N5=0,"Ready now",VLOOKUP($P5,Lists!$D$2:$E$5,2,FALSE)))) -> Assessment pending
A6: 0017000000rXvEBAA0 | B6: Skillsoft Corporation | C6: Tier 2 | D6: AMER | E6: AMER Commercial | F6: Select West | G6: Cohort 1: Upgrades in progress | H6: 112962 | I6: Alan Simpkins | K6: Pending | M6: =IF($B6="","",COUNTIFS('Blocker log'!$A:$A,$B6,'Blocker log'!$G:$G,"<>")) -> 0 | N6: =IF($B6="","",COUNTIFS('Blocker log'!$A:$A,$B6,'Blocker log'!$G:$G,"Hard blocker")) -> 0 | O6: =IF($B6="","",COUNTIFS('Blocker log'!$A:$A,$B6,'Blocker log'!$G:$G,"Hard blocker",'Blocker log'!$L:$L,9)) -> 0 | P6: =IF($B6="","",MAXIFS('Blocker log'!$L:$L,'Blocker log'!$A:$A,$B6,'Blocker log'!$G:$G,"Hard blocker")) -> 0 | Q6: =IF($B6="","",IF($K6<>"Complete","Assessment pending",IF($N6=0,"Ready now",VLOOKUP($P6,Lists!$D$2:$E$5,2,FALSE)))) -> Assessment pending
A7: 0017000000jurAfAAI | B7: MetLife, Inc. | C7: Tier 1 | D7: AMER | E7: AMER Strategic East | F7: AMER Strategic East FIS | G7: Cohort 1: Upgrades in progress | H7: 2191200 | I7: Alex Reshetniak | K7: Complete | L7: 46316 | M7: =IF($B7="","",COUNTIFS('Blocker log'!$A:$A,$B7,'Blocker log'!$G:$G,"<>")) -> 0 | N7: =IF($B7="","",COUNTIFS('Blocker log'!$A:$A,$B7,'Blocker log'!$G:$G,"Hard blocker")) -> 0 | O7: =IF($B7="","",COUNTIFS('Blocker log'!$A:$A,$B7,'Blocker log'!$G:$G,"Hard blocker",'Blocker log'!$L:$L,9)) -> 0 | P7: =IF($B7="","",MAXIFS('Blocker log'!$L:$L,'Blocker log'!$A:$A,$B7,'Blocker log'!$G:$G,"Hard blocker")) -> 0 | Q7: =IF($B7="","",IF($K7<>"Complete","Assessment pending",IF($N7=0,"Ready now",VLOOKUP($P7,Lists!$D$2:$E$5,2,FALSE)))) -> Ready now
A8: 0014u00002BGospAAD | B8: Fed-Tulip38 | C8: Tier 1 | D8: AMER | E8: US Public Sector | F8: SLED Northeast | G8: Cohort 1: Upgrades in progress | H8: 2415715 | M8: =IF($B8="","",COUNTIFS('Blocker log'!$A:$A,$B8,'Blocker log'!$G:$G,"<>")) -> 0 | N8: =IF($B8="","",COUNTIFS('Blocker log'!$A:$A,$B8,'Blocker log'!$G:$G,"Hard blocker")) -> 0 | O8: =IF($B8="","",COUNTIFS('Blocker log'!$A:$A,$B8,'Blocker log'!$G:$G,"Hard blocker",'Blocker log'!$L:$L,9)) -> 0 | P8: =IF($B8="","",MAXIFS('Blocker log'!$L:$L,'Blocker log'!$A:$A,$B8,'Blocker log'!$G:$G,"Hard blocker")) -> 0 | Q8: =IF($B8="","",IF($K8<>"Complete","Assessment pending",IF($N8=0,"Ready now",VLOOKUP($P8,Lists!$D$2:$E$5,2,FALSE)))) -> Assessment pending
A9: 0017000000bFPu8AAG | B9: Equinix, Inc. | C9: Tier 1 | D9: AMER | E9: AMER Strategic West | F9: AMER Strategic West NorCal | G9: Cohort 1: Upgrades in progress | H9: 955532 | I9: Alex Reshetniak | K9: Complete | L9: 46316 | M9: =IF($B9="","",COUNTIFS('Blocker log'!$A:$A,$B9,'Blocker log'!$G:$G,"<>")) -> 0 | N9: =IF($B9="","",COUNTIFS('Blocker log'!$A:$A,$B9,'Blocker log'!$G:$G,"Hard blocker")) -> 0 | O9: =IF($B9="","",COUNTIFS('Blocker log'!$A:$A,$B9,'Blocker log'!$G:$G,"Hard blocker",'Blocker log'!$L:$L,9)) -> 0 | P9: =IF($B9="","",MAXIFS('Blocker log'!$L:$L,'Blocker log'!$A:$A,$B9,'Blocker log'!$G:$G,"Hard blocker")) -> 0 | Q9: =IF($B9="","",IF($K9<>"Complete","Assessment pending",IF($N9=0,"Ready now",VLOOKUP($P9,Lists!$D$2:$E$5,2,FALSE)))) -> Ready now
A10: 0017000000drDq2AAE | B10: Intrado Life & Safety | C10: Tier 2 | D10: AMER | E10: AMER Commercial | F10: Select West | G10: Cohort 1: Upgrades in progress | H10: 376301 | I10: Alex Reshetniak | K10: Complete | L10: 46316 | M10: =IF($B10="","",COUNTIFS('Blocker log'!$A:$A,$B10,'Blocker log'!$G:$G,"<>")) -> 0 | N10: =IF($B10="","",COUNTIFS('Blocker log'!$A:$A,$B10,'Blocker log'!$G:$G,"Hard blocker")) -> 0 | O10: =IF($B10="","",COUNTIFS('Blocker log'!$A:$A,$B10,'Blocker log'!$G:$G,"Hard blocker",'Blocker log'!$L:$L,9)) -> 0 | P10: =IF($B10="","",MAXIFS('Blocker log'!$L:$L,'Blocker log'!$A:$A,$B10,'Blocker log'!$G:$G,"Hard blocker")) -> 0 | Q10: =IF($B10="","",IF($K10<>"Complete","Assessment pending",IF($N10=0,"Ready now",VLOOKUP($P10,Lists!$D$2:$E$5,2,FALSE)))) -> Ready now
A11: 0017000000wKwTRAA0 | B11: Allegiant Travel Company | C11: Tier 2 | D11: AMER | E11: AMER Strategic West | F11: AMER Strategic West MTN | G11: Cohort 1: Upgrades in progress | H11: 210260 | I11: Alex Reshetniak | K11: Complete | L11: 46316 | M11: =IF($B11="","",COUNTIFS('Blocker log'!$A:$A,$B11,'Blocker log'!$G:$G,"<>")) -> 0 | N11: =IF($B11="","",COUNTIFS('Blocker log'!$A:$A,$B11,'Blocker log'!$G:$G,"Hard blocker")) -> 0 | O11: =IF($B11="","",COUNTIFS('Blocker log'!$A:$A,$B11,'Blocker log'!$G:$G,"Hard blocker",'Blocker log'!$L:$L,9)) -> 0 | P11: =IF($B11="","",MAXIFS('Blocker log'!$L:$L,'Blocker log'!$A:$A,$B11,'Blocker log'!$G:$G,"Hard blocker")) -> 0 | Q11: =IF($B11="","",IF($K11<>"Complete","Assessment pending",IF($N11=0,"Ready now",VLOOKUP($P11,Lists!$D$2:$E$5,2,FALSE)))) -> Ready now
A12: 0017000001NUIVSAA5 | B12: Personal Capital Corporation | C12: Tier 2 | D12: AMER | E12: AMER Strategic West | F12: AMER Strategic West MTN | G12: Cohort 1: Upgrades in progress | H12: 189000 | I12: Alex Reshetniak | K12: Complete | L12: 46316 | M12: =IF($B12="","",COUNTIFS('Blocker log'!$A:$A,$B12,'Blocker log'!$G:$G,"<>")) -> 0 | N12: =IF($B12="","",COUNTIFS('Blocker log'!$A:$A,$B12,'Blocker log'!$G:$G,"Hard blocker")) -> 0 | O12: =IF($B12="","",COUNTIFS('Blocker log'!$A:$A,$B12,'Blocker log'!$G:$G,"Hard blocker",'Blocker log'!$L:$L,9)) -> 0 | P12: =IF($B12="","",MAXIFS('Blocker log'!$L:$L,'Blocker log'!$A:$A,$B12,'Blocker log'!$G:$G,"Hard blocker")) -> 0 | Q12: =IF($B12="","",IF($K12<>"Complete","Assessment pending",IF($N12=0,"Ready now",VLOOKUP($P12,Lists!$D$2:$E$5,2,FALSE)))) -> Ready now
A13: 0017000000jFWBeAAO | B13: Novo Nordisk A/S | C13: Tier 1 | D13: EMEA | E13: Nordics | F13: Denmark | G13: Cohort 1: Upgrades in progress | H13: 1131332 | I13: Amir Chamma | K13: Pending | M13: =IF($B13="","",COUNTIFS('Blocker log'!$A:$A,$B13,'Blocker log'!$G:$G,"<>")) -> 0 | N13: 0 | O13: =IF($B13="","",COUNTIFS('Blocker log'!$A:$A,$B13,'Blocker log'!$G:$G,"Hard blocker",'Blocker log'!$L:$L,9)) -> 0 | P13: =IF($B13="","",MAXIFS('Blocker log'!$L:$L,'Blocker log'!$A:$A,$B13,'Blocker log'!$G:$G,"Hard blocker")) -> 0 | Q13: =IF($B13="","",IF($K13<>"Complete","Assessment pending",IF($N13=0,"Ready now",VLOOKUP($P13,Lists!$D$2:$E$5,2,FALSE)))) -> Assessment pending
A14: 0017000000neSduAAE | B14: Ulta Salon, Cosmetics & Fragrance, Inc | C14: Tier 2 | D14: AMER | E14: AMER Strategic Central | F14: AMER Strategic Central Northcentral | G14: Cohort 1: Upgrades in progress | H14: 638281 | I14: Brian Lewis | K14: Complete | L14: 46315 | M14: =IF($B14="","",COUNTIFS('Blocker log'!$A:$A,$B14,'Blocker log'!$G:$G,"<>")) -> 0 | N14: =IF($B14="","",COUNTIFS('Blocker log'!$A:$A,$B14,'Blocker log'!$G:$G,"Hard blocker")) -> 0 | O14: =IF($B14="","",COUNTIFS('Blocker log'!$A:$A,$B14,'Blocker log'!$G:$G,"Hard blocker",'Blocker log'!$L:$L,9)) -> 0 | P14: =IF($B14="","",MAXIFS('Blocker log'!$L:$L,'Blocker log'!$A:$A,$B14,'Blocker log'!$G:$G,"Hard blocker")) -> 0 | Q14: =IF($B14="","",IF($K14<>"Complete","Assessment pending",IF($N14=0,"Ready now",VLOOKUP($P14,Lists!$D$2:$E$5,2,FALSE)))) -> Ready now
A15: 0017000000lAllhAAC | B15: Cardinal Health, Inc. | C15: Tier 2 | D15: AMER | E15: AMER Strategic Central | F15: AMER Strategic Central Ohio Valley | G15: Cohort 1: Upgrades in progress | H15: 379749 | I15: Brian Lewis | K15: Complete | L15: 46315 | M15: =IF($B15="","",COUNTIFS('Blocker log'!$A:$A,$B15,'Blocker log'!$G:$G,"<>")) -> 0 | N15: =IF($B15="","",COUNTIFS('Blocker log'!$A:$A,$B15,'Blocker log'!$G:$G,"Hard blocker")) -> 0 | O15: =IF($B15="","",COUNTIFS('Blocker log'!$A:$A,$B15,'Blocker log'!$G:$G,"Hard blocker",'Blocker log'!$L:$L,9)) -> 0 | P15: =IF($B15="","",MAXIFS('Blocker log'!$L:$L,'Blocker log'!$A:$A,$B15,'Blocker log'!$G:$G,"Hard blocker")) -> 0 | Q15: =IF($B15="","",IF($K15<>"Complete","Assessment pending",IF($N15=0,"Ready now",VLOOKUP($P15,Lists!$D$2:$E$5,2,FALSE)))) -> Ready now
A16: 0017000000cKVeuAAG | B16: HealthPartners, Inc. | C16: Tier 2 | D16: AMER | E16: AMER Strategic West | F16: AMER Strategic West Healthcare West | G16: Cohort 1: Upgrades in progress | H16: 144767 | I16: Brian Lewis | K16: Complete | L16: 46315 | M16: =IF($B16="","",COUNTIFS('Blocker log'!$A:$A,$B16,'Blocker log'!$G:$G,"<>")) -> 0 | N16: =IF($B16="","",COUNTIFS('Blocker log'!$A:$A,$B16,'Blocker log'!$G:$G,"Hard blocker")) -> 0 | O16: =IF($B16="","",COUNTIFS('Blocker log'!$A:$A,$B16,'Blocker log'!$G:$G,"Hard blocker",'Blocker log'!$L:$L,9)) -> 0 | P16: =IF($B16="","",MAXIFS('Blocker log'!$L:$L,'Blocker log'!$A:$A,$B16,'Blocker log'!$G:$G,"Hard blocker")) -> 0 | Q16: =IF($B16="","",IF($K16<>"Complete","Assessment pending",IF($N16=0,"Ready now",VLOOKUP($P16,Lists!$D$2:$E$5,2,FALSE)))) -> Ready now
A17: 0017000000oqq3JAAQ | B17: Engie | C17: Tier 1 | D17: EMEA | E17: France | F17: France Strategic | G17: Cohort 1: Upgrades in progress | H17: 1602702 | I17: Christopher Ley | K17: Pending | M17: =IF($B17="","",COUNTIFS('Blocker log'!$A:$A,$B17,'Blocker log'!$G:$G,"<>")) -> 0 | N17: =IF($B17="","",COUNTIFS('Blocker log'!$A:$A,$B17,'Blocker log'!$G:$G,"Hard blocker")) -> 0 | O17: =IF($B17="","",COUNTIFS('Blocker log'!$A:$A,$B17,'Blocker log'!$G:$G,"Hard blocker",'Blocker log'!$L:$L,9)) -> 0 | P17: =IF($B17="","",MAXIFS('Blocker log'!$L:$L,'Blocker log'!$A:$A,$B17,'Blocker log'!$G:$G,"Hard blocker")) -> 0 | Q17: =IF($B17="","",IF($K17<>"Complete","Assessment pending",IF($N17=0,"Ready now",VLOOKUP($P17,Lists!$D$2:$E$5,2,FALSE)))) -> Assessment pending
A18: 0017000001VuycpAAB | B18: Airbus 1 | C18: Tier 1 | D18: EMEA | E18: France | F18: France Strategic | G18: Cohort 1: Upgrades in progress | H18: 467026 | I18: Daniel Tor | K18: Pending | M18: =IF($B18="","",COUNTIFS('Blocker log'!$A:$A,$B18,'Blocker log'!$G:$G,"<>")) -> 0 | N18: =IF($B18="","",COUNTIFS('Blocker log'!$A:$A,$B18,'Blocker log'!$G:$G,"Hard blocker")) -> 0 | O18: =IF($B18="","",COUNTIFS('Blocker log'!$A:$A,$B18,'Blocker log'!$G:$G,"Hard blocker",'Blocker log'!$L:$L,9)) -> 0 | P18: =IF($B18="","",MAXIFS('Blocker log'!$L:$L,'Blocker log'!$A:$A,$B18,'Blocker log'!$G:$G,"Hard blocker")) -> 0 | Q18: =IF($B18="","",IF($K18<>"Complete","Assessment pending",IF($N18=0,"Ready now",VLOOKUP($P18,Lists!$D$2:$E$5,2,FALSE)))) -> Assessment pending
A19: 0017000000rZ0dmAAC | B19: Sabre GLBL Inc | C19: Tier 1 | D19: AMER | E19: AMER Strategic Central | F19: AMER Strategic Central Texas | G19: Cohort 1: Upgrades in progress | H19: 1751558 | I19: Farooq Abrahem | K19: Pending | M19: =IF($B19="","",COUNTIFS('Blocker log'!$A:$A,$B19,'Blocker log'!$G:$G,"<>")) -> 0 | N19: =IF($B19="","",COUNTIFS('Blocker log'!$A:$A,$B19,'Blocker log'!$G:$G,"Hard blocker")) -> 0 | O19: =IF($B19="","",COUNTIFS('Blocker log'!$A:$A,$B19,'Blocker log'!$G:$G,"Hard blocker",'Blocker log'!$L:$L,9)) -> 0 | P19: =IF($B19="","",MAXIFS('Blocker log'!$L:$L,'Blocker log'!$A:$A,$B19,'Blocker log'!$G:$G,"Hard blocker")) -> 0 | Q19: =IF($B19="","",IF($K19<>"Complete","Assessment pending",IF($N19=0,"Ready now",VLOOKUP($P19,Lists!$D$2:$E$5,2,FALSE)))) -> Assessment pending
A20: 0017000000bF5EOAA0 | B20: The NASDAQ OMX Group, Inc. | C20: Tier 1 | D20: AMER | E20: AMER Strategic East | F20: AMER Strategic East NY Enterprise | G20: Cohort 1: Upgrades in progress | H20: 1247274 | M20: =IF($B20="","",COUNTIFS('Blocker log'!$A:$A,$B20,'Blocker log'!$G:$G,"<>")) -> 0 | N20: =IF($B20="","",COUNTIFS('Blocker log'!$A:$A,$B20,'Blocker log'!$G:$G,"Hard blocker")) -> 0 | O20: =IF($B20="","",COUNTIFS('Blocker log'!$A:$A,$B20,'Blocker log'!$G:$G,"Hard blocker",'Blocker log'!$L:$L,9)) -> 0 | P20: =IF($B20="","",MAXIFS('Blocker log'!$L:$L,'Blocker log'!$A:$A,$B20,'Blocker log'!$G:$G,"Hard blocker")) -> 0 | Q20: =IF($B20="","",IF($K20<>"Complete","Assessment pending",IF($N20=0,"Ready now",VLOOKUP($P20,Lists!$D$2:$E$5,2,FALSE)))) -> Assessment pending
A21: 0017000000mir1qAAA | B21: Texas Children's Hospital | C21: Tier 2 | D21: AMER | E21: AMER Strategic West | F21: AMER Strategic West Healthcare West | G21: Cohort 1: Upgrades in progress | H21: 190663 | I21: Farooq Abrahem | K21: Pending | M21: =IF($B21="","",COUNTIFS('Blocker log'!$A:$A,$B21,'Blocker log'!$G:$G,"<>")) -> 0 | N21: =IF($B21="","",COUNTIFS('Blocker log'!$A:$A,$B21,'Blocker log'!$G:$G,"Hard blocker")) -> 0 | O21: =IF($B21="","",COUNTIFS('Blocker log'!$A:$A,$B21,'Blocker log'!$G:$G,"Hard blocker",'Blocker log'!$L:$L,9)) -> 0 | P21: =IF($B21="","",MAXIFS('Blocker log'!$L:$L,'Blocker log'!$A:$A,$B21,'Blocker log'!$G:$G,"Hard blocker")) -> 0 | Q21: =IF($B21="","",IF($K21<>"Complete","Assessment pending",IF($N21=0,"Ready now",VLOOKUP($P21,Lists!$D$2:$E$5,2,FALSE)))) -> Assessment pending
A22: 0017000000dx6OMAAY | B22: The PNC Financial Services Group, Inc. | C22: Tier 2 | D22: AMER | E22: AMER Strategic Central | F22: AMER Strategic Central Ohio Valley | G22: Cohort 1: Upgrades in progress | H22: 137721 | I22: Farooq Abrahem | K22: Pending | M22: =IF($B22="","",COUNTIFS('Blocker log'!$A:$A,$B22,'Blocker log'!$G:$G,"<>")) -> 0 | N22: =IF($B22="","",COUNTIFS('Blocker log'!$A:$A,$B22,'Blocker log'!$G:$G,"Hard blocker")) -> 0 | O22: =IF($B22="","",COUNTIFS('Blocker log'!$A:$A,$B22,'Blocker log'!$G:$G,"Hard blocker",'Blocker log'!$L:$L,9)) -> 0 | P22: =IF($B22="","",MAXIFS('Blocker log'!$L:$L,'Blocker log'!$A:$A,$B22,'Blocker log'!$G:$G,"Hard blocker")) -> 0 | Q22: =IF($B22="","",IF($K22<>"Complete","Assessment pending",IF($N22=0,"Ready now",VLOOKUP($P22,Lists!$D$2:$E$5,2,FALSE)))) -> Assessment pending
A23: 0017000000MfHihAAF | B23: Franciscan Alliance, Inc. | C23: Tier 2 | D23: AMER | E23: AMER Strategic West | F23: AMER Strategic West Healthcare East | G23: Cohort 1: Upgrades in progress | H23: 161409 | I23: Farooq Abrahem | K23: Pending | M23: =IF($B23="","",COUNTIFS('Blocker log'!$A:$A,$B23,'Blocker log'!$G:$G,"<>")) -> 0 | N23: =IF($B23="","",COUNTIFS('Blocker log'!$A:$A,$B23,'Blocker log'!$G:$G,"Hard blocker")) -> 0 | O23: =IF($B23="","",COUNTIFS('Blocker log'!$A:$A,$B23,'Blocker log'!$G:$G,"Hard blocker",'Blocker log'!$L:$L,9)) -> 0 | P23: =IF($B23="","",MAXIFS('Blocker log'!$L:$L,'Blocker log'!$A:$A,$B23,'Blocker log'!$G:$G,"Hard blocker")) -> 0 | Q23: =IF($B23="","",IF($K23<>"Complete","Assessment pending",IF($N23=0,"Ready now",VLOOKUP($P23,Lists!$D$2:$E$5,2,FALSE)))) -> Assessment pending
A24: 001700000137WgRAAU | B24: Wind River Systems, Inc. | C24: Tier 2 | D24: AMER | E24: AMER Strategic Central | F24: AMER Strategic Central Texas | G24: Cohort 1: Upgrades in progress | H24: 148120 | I24: Farooq Abrahem | K24: Pending | M24: =IF($B24="","",COUNTIFS('Blocker log'!$A:$A,$B24,'Blocker log'!$G:$G,"<>")) -> 0 | N24: =IF($B24="","",COUNTIFS('Blocker log'!$A:$A,$B24,'Blocker log'!$G:$G,"Hard blocker")) -> 0 | O24: =IF($B24="","",COUNTIFS('Blocker log'!$A:$A,$B24,'Blocker log'!$G:$G,"Hard blocker",'Blocker log'!$L:$L,9)) -> 0 | P24: =IF($B24="","",MAXIFS('Blocker log'!$L:$L,'Blocker log'!$A:$A,$B24,'Blocker log'!$G:$G,"Hard blocker")) -> 0 | Q24: =IF($B24="","",IF($K24<>"Complete","Assessment pending",IF($N24=0,"Ready now",VLOOKUP($P24,Lists!$D$2:$E$5,2,FALSE)))) -> Assessment pending
A25: 0017000000kbOIVAA2 | B25: Lg Uplus Corp. | C25: Tier 1 | D25: JAPAC | E25: Korea | F25: Korea | G25: Cohort 1: Upgrades in progress | H25: 755874 | I25: Jane Shin | K25: Pending | M25: =IF($B25="","",COUNTIFS('Blocker log'!$A:$A,$B25,'Blocker log'!$G:$G,"<>")) -> 0 | N25: =IF($B25="","",COUNTIFS('Blocker log'!$A:$A,$B25,'Blocker log'!$G:$G,"Hard blocker")) -> 0 | O25: =IF($B25="","",COUNTIFS('Blocker log'!$A:$A,$B25,'Blocker log'!$G:$G,"Hard blocker",'Blocker log'!$L:$L,9)) -> 0 | P25: =IF($B25="","",MAXIFS('Blocker log'!$L:$L,'Blocker log'!$A:$A,$B25,'Blocker log'!$G:$G,"Hard blocker")) -> 0 | Q25: =IF($B25="","",IF($K25<>"Complete","Assessment pending",IF($N25=0,"Ready now",VLOOKUP($P25,Lists!$D$2:$E$5,2,FALSE)))) -> Assessment pending
A26: 0017000000dN3dfAAC | B26: Salesforce.Com, Inc. | C26: Tier 1 | D26: AMER | E26: AMER Strategic West | F26: AMER Strategic West NorCal | G26: Cohort 1: Upgrades in progress | H26: 13604812 | I26: Khizar Karim | K26: Pending | M26: =IF($B26="","",COUNTIFS('Blocker log'!$A:$A,$B26,'Blocker log'!$G:$G,"<>")) -> 0 | N26: =IF($B26="","",COUNTIFS('Blocker log'!$A:$A,$B26,'Blocker log'!$G:$G,"Hard blocker")) -> 0 | O26: =IF($B26="","",COUNTIFS('Blocker log'!$A:$A,$B26,'Blocker log'!$G:$G,"Hard blocker",'Blocker log'!$L:$L,9)) -> 0 | P26: =IF($B26="","",MAXIFS('Blocker log'!$L:$L,'Blocker log'!$A:$A,$B26,'Blocker log'!$G:$G,"Hard blocker")) -> 0 | Q26: =IF($B26="","",IF($K26<>"Complete","Assessment pending",IF($N26=0,"Ready now",VLOOKUP($P26,Lists!$D$2:$E$5,2,FALSE)))) -> Assessment pending
A27: 0017000000qx0YBAAY | B27: Marriott International, Inc. | C27: Tier 1 | D27: AMER | E27: AMER Strategic East | F27: AMER Strategic East MidAtlantic | G27: Cohort 1: Upgrades in progress | H27: 1159779 | I27: Khizar Karim | K27: Pending | M27: =IF($B27="","",COUNTIFS('Blocker log'!$A:$A,$B27,'Blocker log'!$G:$G,"<>")) -> 0 | N27: =IF($B27="","",COUNTIFS('Blocker log'!$A:$A,$B27,'Blocker log'!$G:$G,"Hard blocker")) -> 0 | O27: =IF($B27="","",COUNTIFS('Blocker log'!$A:$A,$B27,'Blocker log'!$G:$G,"Hard blocker",'Blocker log'!$L:$L,9)) -> 0 | P27: =IF($B27="","",MAXIFS('Blocker log'!$L:$L,'Blocker log'!$A:$A,$B27,'Blocker log'!$G:$G,"Hard blocker")) -> 0 | Q27: =IF($B27="","",IF($K27<>"Complete","Assessment pending",IF($N27=0,"Ready now",VLOOKUP($P27,Lists!$D$2:$E$5,2,FALSE)))) -> Assessment pending
A28: 0014u00001tEzw8AAC | B28: Dh Business Services Llc | C28: Tier 1 | D28: AMER | E28: AMER Strategic East | F28: AMER Strategic East Northeast | G28: Cohort 1: Upgrades in progress | H28: 773 | I28: Khizar Karim | K28: Pending | M28: =IF($B28="","",COUNTIFS('Blocker log'!$A:$A,$B28,'Blocker log'!$G:$G,"<>")) -> 0 | N28: =IF($B28="","",COUNTIFS('Blocker log'!$A:$A,$B28,'Blocker log'!$G:$G,"Hard blocker")) -> 0 | O28: =IF($B28="","",COUNTIFS('Blocker log'!$A:$A,$B28,'Blocker log'!$G:$G,"Hard blocker",'Blocker log'!$L:$L,9)) -> 0 | P28: =IF($B28="","",MAXIFS('Blocker log'!$L:$L,'Blocker log'!$A:$A,$B28,'Blocker log'!$G:$G,"Hard blocker")) -> 0 | Q28: =IF($B28="","",IF($K28<>"Complete","Assessment pending",IF($N28=0,"Ready now",VLOOKUP($P28,Lists!$D$2:$E$5,2,FALSE)))) -> Assessment pending
A29: 0017000000peq8uAAA | B29: Tory Burch LLC | C29: Tier 2 | D29: AMER | E29: AMER Strategic East | F29: AMER Strategic East NY Enterprise | G29: Cohort 1: Upgrades in progress | H29: 191798 | I29: Khizar Karim | K29: Pending | M29: =IF($B29="","",COUNTIFS('Blocker log'!$A:$A,$B29,'Blocker log'!$G:$G,"<>")) -> 0 | N29: =IF($B29="","",COUNTIFS('Blocker log'!$A:$A,$B29,'Blocker log'!$G:$G,"Hard blocker")) -> 0 | O29: =IF($B29="","",COUNTIFS('Blocker log'!$A:$A,$B29,'Blocker log'!$G:$G,"Hard blocker",'Blocker log'!$L:$L,9)) -> 0 | P29: =IF($B29="","",MAXIFS('Blocker log'!$L:$L,'Blocker log'!$A:$A,$B29,'Blocker log'!$G:$G,"Hard blocker")) -> 0 | Q29: =IF($B29="","",IF($K29<>"Complete","Assessment pending",IF($N29=0,"Ready now",VLOOKUP($P29,Lists!$D$2:$E$5,2,FALSE)))) -> Assessment pending
A30: 0017000000nBDuXAAW | B30: Factory Mutual Insurance Co | C30: Tier 2 | D30: AMER | E30: AMER Strategic East | F30: AMER Strategic East Northeast | G30: Cohort 1: Upgrades in progress | I30: Khizar Karim | K30: Pending | M30: =IF($B30="","",COUNTIFS('Blocker log'!$A:$A,$B30,'Blocker log'!$G:$G,"<>")) -> 0 | N30: =IF($B30="","",COUNTIFS('Blocker log'!$A:$A,$B30,'Blocker log'!$G:$G,"Hard blocker")) -> 0 | O30: =IF($B30="","",COUNTIFS('Blocker log'!$A:$A,$B30,'Blocker log'!$G:$G,"Hard blocker",'Blocker log'!$L:$L,9)) -> 0 | P30: =IF($B30="","",MAXIFS('Blocker log'!$L:$L,'Blocker log'!$A:$A,$B30,'Blocker log'!$G:$G,"Hard blocker")) -> 0 | Q30: =IF($B30="","",IF($K30<>"Complete","Assessment pending",IF($N30=0,"Ready now",VLOOKUP($P30,Lists!$D$2:$E$5,2,FALSE)))) -> Assessment pending
A31: 0017000000cJCU8AAO | B31: Cox Communications, Inc. | C31: Tier 1 | D31: AMER | E31: AMER Strategic East | F31: AMER Strategic East SI/SP | G31: Cohort 1: Upgrades in progress | H31: 55880 | I31: Lauren Megrelis | K31: Pending | M31: =IF($B31="","",COUNTIFS('Blocker log'!$A:$A,$B31,'Blocker log'!$G:$G,"<>")) -> 0 | N31: =IF($B31="","",COUNTIFS('Blocker log'!$A:$A,$B31,'Blocker log'!$G:$G,"Hard blocker")) -> 0 | O31: =IF($B31="","",COUNTIFS('Blocker log'!$A:$A,$B31,'Blocker log'!$G:$G,"Hard blocker",'Blocker log'!$L:$L,9)) -> 0 | P31: =IF($B31="","",MAXIFS('Blocker log'!$L:$L,'Blocker log'!$A:$A,$B31,'Blocker log'!$G:$G,"Hard blocker")) -> 0 | Q31: =IF($B31="","",IF($K31<>"Complete","Assessment pending",IF($N31=0,"Ready now",VLOOKUP($P31,Lists!$D$2:$E$5,2,FALSE)))) -> Assessment pending
A32: 0017000000jEETMAA4 | B32: Medidata Solutions Worldwide | C32: Tier 1 | D32: AMER | E32: AMER Strategic East | F32: AMER Strategic East NY Enterprise | G32: Cohort 1: Upgrades in progress | H32: 807516 | I32: Lauren Megrelis | K32: Pending | M32: =IF($B32="","",COUNTIFS('Blocker log'!$A:$A,$B32,'Blocker log'!$G:$G,"<>")) -> 0 | N32: =IF($B32="","",COUNTIFS('Blocker log'!$A:$A,$B32,'Blocker log'!$G:$G,"Hard blocker")) -> 0 | O32: =IF($B32="","",COUNTIFS('Blocker log'!$A:$A,$B32,'Blocker log'!$G:$G,"Hard blocker",'Blocker log'!$L:$L,9)) -> 0 | P32: =IF($B32="","",MAXIFS('Blocker log'!$L:$L,'Blocker log'!$A:$A,$B32,'Blocker log'!$G:$G,"Hard blocker")) -> 0 | Q32: =IF($B32="","",IF($K32<>"Complete","Assessment pending",IF($N32=0,"Ready now",VLOOKUP($P32,Lists!$D$2:$E$5,2,FALSE)))) -> Assessment pending
A33: 0017000001V49vrAAB | B33: Everbridge, Inc. | C33: Tier 2 | D33: AMER | E33: AMER Commercial | F33: Select East | G33: Cohort 1: Upgrades in progress | H33: 63515 | I33: Lauren Megrelis | K33: Pending | M33: =IF($B33="","",COUNTIFS('Blocker log'!$A:$A,$B33,'Blocker log'!$G:$G,"<>")) -> 0 | N33: =IF($B33="","",COUNTIFS('Blocker log'!$A:$A,$B33,'Blocker log'!$G:$G,"Hard blocker")) -> 0 | O33: =IF($B33="","",COUNTIFS('Blocker log'!$A:$A,$B33,'Blocker log'!$G:$G,"Hard blocker",'Blocker log'!$L:$L,9)) -> 0 | P33: =IF($B33="","",MAXIFS('Blocker log'!$L:$L,'Blocker log'!$A:$A,$B33,'Blocker log'!$G:$G,"Hard blocker")) -> 0 | Q33: =IF($B33="","",IF($K33<>"Complete","Assessment pending",IF($N33=0,"Ready now",VLOOKUP($P33,Lists!$D$2:$E$5,2,FALSE)))) -> Assessment pending
A34: 0017000000t9fPSAAY | B34: Memorial Sloan-Kettering Cancer Center | C34: Tier 2 | D34: AMER | E34: AMER Strategic West | F34: AMER Strategic West Healthcare East | G34: Cohort 1: Upgrades in progress | H34: 223497 | I34: Lauren Megrelis | K34: Pending | M34: =IF($B34="","",COUNTIFS('Blocker log'!$A:$A,$B34,'Blocker log'!$G:$G,"<>")) -> 0 | N34: =IF($B34="","",COUNTIFS('Blocker log'!$A:$A,$B34,'Blocker log'!$G:$G,"Hard blocker")) -> 0 | O34: =IF($B34="","",COUNTIFS('Blocker log'!$A:$A,$B34,'Blocker log'!$G:$G,"Hard blocker",'Blocker log'!$L:$L,9)) -> 0 | P34: =IF($B34="","",MAXIFS('Blocker log'!$L:$L,'Blocker log'!$A:$A,$B34,'Blocker log'!$G:$G,"Hard blocker")) -> 0 | Q34: =IF($B34="","",IF($K34<>"Complete","Assessment pending",IF($N34=0,"Ready now",VLOOKUP($P34,Lists!$D$2:$E$5,2,FALSE)))) -> Assessment pending
A35: 0014u0000238d8uAAA | B35: Corebridge Financial, Inc. | C35: Tier 1 | D35: AMER | E35: AMER Strategic East | F35: AMER Strategic East FIS | G35: Cohort 1: Upgrades in progress | H35: 36000 | M35: =IF($B35="","",COUNTIFS('Blocker log'!$A:$A,$B35,'Blocker log'!$G:$G,"<>")) -> 0 | N35: =IF($B35="","",COUNTIFS('Blocker log'!$A:$A,$B35,'Blocker log'!$G:$G,"Hard blocker")) -> 0 | O35: =IF($B35="","",COUNTIFS('Blocker log'!$A:$A,$B35,'Blocker log'!$G:$G,"Hard blocker",'Blocker log'!$L:$L,9)) -> 0 | P35: =IF($B35="","",MAXIFS('Blocker log'!$L:$L,'Blocker log'!$A:$A,$B35,'Blocker log'!$G:$G,"Hard blocker")) -> 0 | Q35: =IF($B35="","",IF($K35<>"Complete","Assessment pending",IF($N35=0,"Ready now",VLOOKUP($P35,Lists!$D$2:$E$5,2,FALSE)))) -> Assessment pending
A36: 0014u000029psomAAA | B36: Optus Systems Pty Ltd | C36: Tier 1 | D36: JAPAC | E36: ANZ | F36: ANZ East Coast Majors | G36: Cohort 1: Upgrades in progress | H36: 325882 | M36: =IF($B36="","",COUNTIFS('Blocker log'!$A:$A,$B36,'Blocker log'!$G:$G,"<>")) -> 0 | N36: =IF($B36="","",COUNTIFS('Blocker log'!$A:$A,$B36,'Blocker log'!$G:$G,"Hard blocker")) -> 0 | O36: =IF($B36="","",COUNTIFS('Blocker log'!$A:$A,$B36,'Blocker log'!$G:$G,"Hard blocker",'Blocker log'!$L:$L,9)) -> 0 | P36: =IF($B36="","",MAXIFS('Blocker log'!$L:$L,'Blocker log'!$A:$A,$B36,'Blocker log'!$G:$G,"Hard blocker")) -> 0 | Q36: =IF($B36="","",IF($K36<>"Complete","Assessment pending",IF($N36=0,"Ready now",VLOOKUP($P36,Lists!$D$2:$E$5,2,FALSE)))) -> Assessment pending
A37: 0017000000bFh2TAAS | B37: The Chubb Corporation | C37: Tier 1 | D37: AMER | E37: AMER Strategic East | F37: AMER Strategic East FIS | G37: Cohort 1: Upgrades in progress | H37: 735868 | M37: =IF($B37="","",COUNTIFS('Blocker log'!$A:$A,$B37,'Blocker log'!$G:$G,"<>")) -> 0 | N37: =IF($B37="","",COUNTIFS('Blocker log'!$A:$A,$B37,'Blocker log'!$G:$G,"Hard blocker")) -> 0 | O37: =IF($B37="","",COUNTIFS('Blocker log'!$A:$A,$B37,'Blocker log'!$G:$G,"Hard blocker",'Blocker log'!$L:$L,9)) -> 0 | P37: =IF($B37="","",MAXIFS('Blocker log'!$L:$L,'Blocker log'!$A:$A,$B37,'Blocker log'!$G:$G,"Hard blocker")) -> 0 | Q37: =IF($B37="","",IF($K37<>"Complete","Assessment pending",IF($N37=0,"Ready now",VLOOKUP($P37,Lists!$D$2:$E$5,2,FALSE)))) -> Assessment pending
A38: 0014u00001x8rNFAAY | B38: Movable Ink | C38: Tier 2 | D38: AMER | E38: AMER Commercial | F38: Select East | G38: Cohort 1: Upgrades in progress | H38: 155635 | I38: Lauren Megrelis | K38: Pending | M38: =IF($B38="","",COUNTIFS('Blocker log'!$A:$A,$B38,'Blocker log'!$G:$G,"<>")) -> 0 | N38: =IF($B38="","",COUNTIFS('Blocker log'!$A:$A,$B38,'Blocker log'!$G:$G,"Hard blocker")) -> 0 | O38: =IF($B38="","",COUNTIFS('Blocker log'!$A:$A,$B38,'Blocker log'!$G:$G,"Hard blocker",'Blocker log'!$L:$L,9)) -> 0 | P38: =IF($B38="","",MAXIFS('Blocker log'!$L:$L,'Blocker log'!$A:$A,$B38,'Blocker log'!$G:$G,"Hard blocker")) -> 0 | Q38: =IF($B38="","",IF($K38<>"Complete","Assessment pending",IF($N38=0,"Ready now",VLOOKUP($P38,Lists!$D$2:$E$5,2,FALSE)))) -> Assessment pending
A39: 0017000000RGL6UAAX | B39: American Express Company | C39: Tier 1 | D39: AMER | E39: AMER Strategic West | F39: AMER Strategic West MTN | G39: Cohort 1: Upgrades in progress | H39: 1872802 | I39: Lindsey Smith | K39: Pending | M39: =IF($B39="","",COUNTIFS('Blocker log'!$A:$A,$B39,'Blocker log'!$G:$G,"<>")) -> 0 | N39: =IF($B39="","",COUNTIFS('Blocker log'!$A:$A,$B39,'Blocker log'!$G:$G,"Hard blocker")) -> 0 | O39: =IF($B39="","",COUNTIFS('Blocker log'!$A:$A,$B39,'Blocker log'!$G:$G,"Hard blocker",'Blocker log'!$L:$L,9)) -> 0 | P39: =IF($B39="","",MAXIFS('Blocker log'!$L:$L,'Blocker log'!$A:$A,$B39,'Blocker log'!$G:$G,"Hard blocker")) -> 0 | Q39: =IF($B39="","",IF($K39<>"Complete","Assessment pending",IF($N39=0,"Ready now",VLOOKUP($P39,Lists!$D$2:$E$5,2,FALSE)))) -> Assessment pending
A40: 0017000000peemgAAA | B40: Micron Technologies, Inc | C40: Tier 2 | D40: AMER | E40: AMER Strategic West | F40: AMER Strategic West PNW | G40: Cohort 1: Upgrades in progress | H40: 667543 | I40: Lindsey Smith | K40: Pending | M40: =IF($B40="","",COUNTIFS('Blocker log'!$A:$A,$B40,'Blocker log'!$G:$G,"<>")) -> 0 | N40: =IF($B40="","",COUNTIFS('Blocker log'!$A:$A,$B40,'Blocker log'!$G:$G,"Hard blocker")) -> 0 | O40: =IF($B40="","",COUNTIFS('Blocker log'!$A:$A,$B40,'Blocker log'!$G:$G,"Hard blocker",'Blocker log'!$L:$L,9)) -> 0 | P40: =IF($B40="","",MAXIFS('Blocker log'!$L:$L,'Blocker log'!$A:$A,$B40,'Blocker log'!$G:$G,"Hard blocker")) -> 0 | Q40: =IF($B40="","",IF($K40<>"Complete","Assessment pending",IF($N40=0,"Ready now",VLOOKUP($P40,Lists!$D$2:$E$5,2,FALSE)))) -> Assessment pending
...

Sheet Blocker log
A1: Account | B1: Gap | C1: Planned release | D1: Default view | E1: PM owner | F1: Telemetry signal | G1: Customer outcome | H1: Description / how they use it (scale) | I1: Workaround and who delivers it | J1: Telemetry matched customer? | K1: Sprint | L1: Release rank | M1: Escalate? | N1: Date validated | O1: Notes
A2: Example Corp (ignore this row) | B2: Audit Asset Trail | C2: {=IF($B2="","",INDEX('Gap reference'!$C$2:$C$60,MATCH($B2,'Gap reference'!$A$2:$A$60,0)))} -> #N/A | D2: {=IF($B2="","",INDEX('Gap reference'!$D$2:$D$60,MATCH($B2,'Gap reference'!$A$2:$A$60,0)))} -> #N/A | E2: {=IF($B2="","",INDEX('Gap reference'!$G$2:$G$60,MATCH($B2,'Gap reference'!$A$2:$A$60,0)))} -> #N/A | F2: Flagged | G2: Hard blocker | H2: TKG clusters run about 40% of production workloads | J2: Yes | L2: =IF($B2="","",VLOOKUP($C2,Lists!$A$2:$B$10,2,FALSE)) -> #N/A | M2: =IF(AND($G2="Hard blocker",$L2=9),"Yes","") -> #N/A | N2: 46303
A3: Example Corp (ignore this row) | B3: RQL to XQL custom rules | C3: {=IF($B3="","",INDEX('Gap reference'!$C$2:$C$60,MATCH($B3,'Gap reference'!$A$2:$A$60,0)))} -> Oct 2026 to Jan 2027 | D3: {=IF($B3="","",INDEX('Gap reference'!$D$2:$D$60,MATCH($B3,'Gap reference'!$A$2:$A$60,0)))} -> Major blocker | E3: {=IF($B3="","",INDEX('Gap reference'!$G$2:$G$60,MATCH($B3,'Gap reference'!$A$2:$A$60,0)))} -> Ashwin Manekar | F3: Flagged | G3: Workaround accepted | H3: ~120 custom rules; 15 fail translation | I3: PS rewrites the 15 failing rules before cutover | J3: Yes | L3: =IF($B3="","",VLOOKUP($C3,Lists!$A$2:$B$10,2,FALSE)) -> 2 | M3: =IF(AND($G3="Hard blocker",$L3=9),"Yes","") | N3: 46303
A4: Example Corp (ignore this row) | B4: GuardDuty ingestion | C4: {=IF($B4="","",INDEX('Gap reference'!$C$2:$C$60,MATCH($B4,'Gap reference'!$A$2:$A$60,0)))} -> Jan 2027 | D4: {=IF($B4="","",INDEX('Gap reference'!$D$2:$D$60,MATCH($B4,'Gap reference'!$A$2:$A$60,0)))} -> Validate in discovery | E4: {=IF($B4="","",INDEX('Gap reference'!$G$2:$G$60,MATCH($B4,'Gap reference'!$A$2:$A$60,0)))} -> Elad Shuster | F4: Flagged | G4: Not needed | H4: Findings duplicate Cortex Cloud detections | J4: No, flagged but not used | L4: =IF($B4="","",VLOOKUP($C4,Lists!$A$2:$B$10,2,FALSE)) -> 2 | M4: =IF(AND($G4="Hard blocker",$L4=9),"Yes","") | N4: 46303
A5: The Charles Schwab Corporation | B5: RQL to XQL custom rules | C5: {=IF($B5="","",INDEX('Gap reference'!$C$2:$C$60,MATCH($B5,'Gap reference'!$A$2:$A$60,0)))} -> Oct 2026 to Jan 2027 | D5: {=IF($B5="","",INDEX('Gap reference'!$D$2:$D$60,MATCH($B5,'Gap reference'!$A$2:$A$60,0)))} -> Major blocker | E5: {=IF($B5="","",INDEX('Gap reference'!$G$2:$G$60,MATCH($B5,'Gap reference'!$A$2:$A$60,0)))} -> Ashwin Manekar | F5: Flagged | G5: Workaround accepted | H5: 367 run policies with RQL in scope (518 total incl. 151 build). 315 translated as of Oct 22; just under 40 remaining. | I5: PS (Phelipe) translating by hand; Schwab (Ladi) correcting defects in its own RQL. | J5: Yes | L5: =IF($B5="","",VLOOKUP($C5,Lists!$A$2:$B$10,2,FALSE)) -> 2 | M5: =IF(AND($G5="Hard blocker",$L5=9),"Yes","") | N5: 46317 | O5: Telemetry counts 601 custom policies vs 518; reconciling.
A6: The Charles Schwab Corporation | B6: Terraform provider gaps | C6: {=IF($B6="","",INDEX('Gap reference'!$C$2:$C$60,MATCH($B6,'Gap reference'!$A$2:$A$60,0)))} -> Jan 2027 | D6: {=IF($B6="","",INDEX('Gap reference'!$D$2:$D$60,MATCH($B6,'Gap reference'!$A$2:$A$60,0)))} -> Major blocker | E6: {=IF($B6="","",INDEX('Gap reference'!$G$2:$G$60,MATCH($B6,'Gap reference'!$A$2:$A$60,0)))} -> Ashwin Manekar | F6: No telemetry | G6: Hard blocker | H6: Schwab manages rules, policies and compliance controls through the Terraform provider after deployment (COE 524). | J6: No telemetry | L6: =IF($B6="","",VLOOKUP($C6,Lists!$A$2:$B$10,2,FALSE)) -> 2 | N6: 46314 | O6: Production control creation failure (04248274 / XSUP-78801) routed to David as a bug.
A7: The Charles Schwab Corporation | B7: Asset audit trail | C7: {=IF($B7="","",INDEX('Gap reference'!$C$2:$C$60,MATCH($B7,'Gap reference'!$A$2:$A$60,0)))} -> H1 CY2027 (Internal) | D7: {=IF($B7="","",INDEX('Gap reference'!$D$2:$D$60,MATCH($B7,'Gap reference'!$A$2:$A$60,0)))} -> Major blocker | E7: {=IF($B7="","",INDEX('Gap reference'!$G$2:$G$60,MATCH($B7,'Gap reference'!$A$2:$A$60,0)))} -> Guy Liberman | F7: Flagged | G7: Unknown | H7: 15 asset audit trail API calls in 30 days. Ladi (Oct 22): nothing critical depends on it, from memory. | L7: =IF($B7="","",VLOOKUP($C7,Lists!$A$2:$B$10,2,FALSE)) -> #N/A | O7: Confirming with Justin; tracing the API caller.
A8: The Charles Schwab Corporation | B8: Terraform onboarding (full lifecycle) | C8: {=IF($B8="","",INDEX('Gap reference'!$C$2:$C$60,MATCH($B8,'Gap reference'!$A$2:$A$60,0)))} -> Oct 2026 | D8: {=IF($B8="","",INDEX('Gap reference'!$D$2:$D$60,MATCH($B8,'Gap reference'!$A$2:$A$60,0)))} -> Major blocker | E8: {=IF($B8="","",INDEX('Gap reference'!$G$2:$G$60,MATCH($B8,'Gap reference'!$A$2:$A$60,0)))} -> Ashwin Manekar | F8: No telemetry | G8: Unknown | H8: Schwab rejected the standard onboarding template and wants it customized; Azure service principal created through Terraform. | I8: Service principal via azuread_service_principal from the wizard app ID. | J8: No telemetry | L8: =IF($B8="","",VLOOKUP($C8,Lists!$A$2:$B$10,2,FALSE)) -> 1
A9: The Charles Schwab Corporation | B9: Jira ticketing for issues | C9: {=IF($B9="","",INDEX('Gap reference'!$C$2:$C$60,MATCH($B9,'Gap reference'!$A$2:$A$60,0)))} -> #N/A | D9: {=IF($B9="","",INDEX('Gap reference'!$D$2:$D$60,MATCH($B9,'Gap reference'!$A$2:$A$60,0)))} -> #N/A | E9: {=IF($B9="","",INDEX('Gap reference'!$G$2:$G$60,MATCH($B9,'Gap reference'!$A$2:$A$60,0)))} -> #N/A | F9: No telemetry | G9: Hard blocker | H9: Cortex Cloud issues must open Jira tickets automatically; Schwab named it an open cutover blocker. | J9: No telemetry | L9: =IF($B9="","",VLOOKUP($C9,Lists!$A$2:$B$10,2,FALSE)) -> #N/A | N9: 46311 | O9: Owner per Ashwin, Oct 23: notifications (Guy Liberman). Specifics being confirmed with Schwab.
A10: The Charles Schwab Corporation | B10: Compliance categories via API | C10: {=IF($B10="","",INDEX('Gap reference'!$C$2:$C$60,MATCH($B10,'Gap reference'!$A$2:$A$60,0)))} -> #N/A | D10: {=IF($B10="","",INDEX('Gap reference'!$D$2:$D$60,MATCH($B10,'Gap reference'!$A$2:$A$60,0)))} -> #N/A | E10: {=IF($B10="","",INDEX('Gap reference'!$G$2:$G$60,MATCH($B10,'Gap reference'!$A$2:$A$60,0)))} -> #N/A | F10: No telemetry | G10: Hard blocker | H10: Schwab builds custom compliance standards and subcategories through the API (case 04194314). | J10: No telemetry | L10: =IF($B10="","",VLOOKUP($C10,Lists!$A$2:$B$10,2,FALSE)) -> #N/A | N10: 46267 | O10: Production vs test subcategory difference routed to David as a bug.
A11: The Charles Schwab Corporation | B11: Asset groups from cloud account tags | C11: {=IF($B11="","",INDEX('Gap reference'!$C$2:$C$60,MATCH($B11,'Gap reference'!$A$2:$A$60,0)))} -> #N/A | D11: {=IF($B11="","",INDEX('Gap reference'!$D$2:$D$60,MATCH($B11,'Gap reference'!$A$2:$A$60,0)))} -> #N/A | E11: {=IF($B11="","",INDEX('Gap reference'!$G$2:$G$60,MATCH($B11,'Gap reference'!$A$2:$A$60,0)))} -> #N/A | F11: No telemetry | G11: Workaround accepted | H11: Ownership and access are organized by cloud account tags; asset groups and business applications must inherit them. | I11: PS automation (Phelipe) creates asset groups and business applications from tags. | J11: No telemetry | L11: =IF($B11="","",VLOOKUP($C11,Lists!$A$2:$B$10,2,FALSE)) -> #N/A | N11: 46315
A12: The Charles Schwab Corporation | B12: IP-in-CIDR search on firewall rules | C12: {=IF($B12="","",INDEX('Gap reference'!$C$2:$C$60,MATCH($B12,'Gap reference'!$A$2:$A$60,0)))} -> #N/A | D12: {=IF($B12="","",INDEX('Gap reference'!$D$2:$D$60,MATCH($B12,'Gap reference'!$A$2:$A$60,0)))} -> #N/A | E12: {=IF($B12="","",INDEX('Gap reference'!$G$2:$G$60,MATCH($B12,'Gap reference'!$A$2:$A$60,0)))} -> #N/A | F12: No telemetry | G12: Workaround accepted | H12: Schwab looks up every GCP firewall rule allowing a given IP; 192 VPC rules plus firewall policies. | I12: XQL lookup validated in Schwab's tenant (TSE); no automatic flagging. | J12: No telemetry | L12: =IF($B12="","",VLOOKUP($C12,Lists!$A$2:$B$10,2,FALSE)) -> #N/A | N12: 46311 | O12: XPANDR-15405
A13: The Charles Schwab Corporation | B13: GCP address group resolution | C13: {=IF($B13="","",INDEX('Gap reference'!$C$2:$C$60,MATCH($B13,'Gap reference'!$A$2:$A$60,0)))} -> #N/A | D13: {=IF($B13="","",INDEX('Gap reference'!$D$2:$D$60,MATCH($B13,'Gap reference'!$A$2:$A$60,0)))} -> #N/A | E13: {=IF($B13="","",INDEX('Gap reference'!$G$2:$G$60,MATCH($B13,'Gap reference'!$A$2:$A$60,0)))} -> #N/A | F13: No telemetry | G13: Unknown | H13: Whether Schwab's firewall policies reference address groups is not yet confirmed. | J13: No telemetry | L13: =IF($B13="","",VLOOKUP($C13,Lists!$A$2:$B$10,2,FALSE)) -> #N/A | O13: XPANDR-15404, 15401
A14: The Charles Schwab Corporation | B14: AWS audit logs without SNS | C14: {=IF($B14="","",INDEX('Gap reference'!$C$2:$C$60,MATCH($B14,'Gap reference'!$A$2:$A$60,0)))} -> #N/A | D14: {=IF($B14="","",INDEX('Gap reference'!$D$2:$D$60,MATCH($B14,'Gap reference'!$A$2:$A$60,0)))} -> #N/A | E14: {=IF($B14="","",INDEX('Gap reference'!$G$2:$G$60,MATCH($B14,'Gap reference'!$A$2:$A$60,0)))} -> #N/A | F14: No telemetry | G14: Unknown | H14: Schwab asked for EventBridge S3 event format and S3 to SQS delivery without SNS. | I14: SNS intermediary per deployment guidelines; acceptability not confirmed. | J14: No telemetry | L14: =IF($B14="","",VLOOKUP($C14,Lists!$A$2:$B$10,2,FALSE)) -> #N/A | O14: Specialist review requested Oct 5.
A15: The Charles Schwab Corporation | B15: Default policy parity | C15: {=IF($B15="","",INDEX('Gap reference'!$C$2:$C$60,MATCH($B15,'Gap reference'!$A$2:$A$60,0)))} -> #N/A | D15: {=IF($B15="","",INDEX('Gap reference'!$D$2:$D$60,MATCH($B15,'Gap reference'!$A$2:$A$60,0)))} -> #N/A | E15: {=IF($B15="","",INDEX('Gap reference'!$G$2:$G$60,MATCH($B15,'Gap reference'!$A$2:$A$60,0)))} -> #N/A | F15: No telemetry | G15: Unknown | H15: Justin asked for parity with Prisma Cloud default policies (Sep 10); scope not defined. | J15: No telemetry | L15: =IF($B15="","",VLOOKUP($C15,Lists!$A$2:$B$10,2,FALSE)) -> #N/A
A16: The Charles Schwab Corporation | B16: Image age lineage for rehydration evidence | C16: {=IF($B16="","",INDEX('Gap reference'!$C$2:$C$60,MATCH($B16,'Gap reference'!$A$2:$A$60,0)))} -> #N/A | D16: {=IF($B16="","",INDEX('Gap reference'!$D$2:$D$60,MATCH($B16,'Gap reference'!$A$2:$A$60,0)))} -> #N/A | E16: {=IF($B16="","",INDEX('Gap reference'!$G$2:$G$60,MATCH($B16,'Gap reference'!$A$2:$A$60,0)))} -> #N/A | F16: No telemetry | G16: Unknown | H16: Vulnerability management must show auditors that every workload was built from an image passed within 30 days. Prisma maps workload age to parent image age today. | J16: No telemetry | L16: =IF($B16="","",VLOOKUP($C16,Lists!$A$2:$B$10,2,FALSE)) -> #N/A | O16: Schwab mapping requirements, about two weeks (Oct 21). Rules API row (04220471) removed: bug to David.
A17: The Charles Schwab Corporation | B17: GCP Parameter Manager ingestion | C17: {=IF($B17="","",INDEX('Gap reference'!$C$2:$C$60,MATCH($B17,'Gap reference'!$A$2:$A$60,0)))} -> #N/A | D17: {=IF($B17="","",INDEX('Gap reference'!$D$2:$D$60,MATCH($B17,'Gap reference'!$A$2:$A$60,0)))} -> #N/A | E17: {=IF($B17="","",INDEX('Gap reference'!$G$2:$G$60,MATCH($B17,'Gap reference'!$A$2:$A$60,0)))} -> #N/A | F17: No telemetry | G17: Unknown | H17: Feature request (describe, list, versions) for IAM controls and audit logging; expected Nov 22. | J17: No telemetry | L17: =IF($B17="","",VLOOKUP($C17,Lists!$A$2:$B$10,2,FALSE)) -> #N/A
A18: The Charles Schwab Corporation | B18: Lambda image attributes in inventory | C18: {=IF($B18="","",INDEX('Gap reference'!$C$2:$C$60,MATCH($B18,'Gap reference'!$A$2:$A$60,0)))} -> #N/A | D18: {=IF($B18="","",INDEX('Gap reference'!$D$2:$D$60,MATCH($B18,'Gap reference'!$A$2:$A$60,0)))} -> #N/A | E18: {=IF($B18="","",INDEX('Gap reference'!$G$2:$G$60,MATCH($B18,'Gap reference'!$A$2:$A$60,0)))} -> #N/A | F18: No telemetry | G18: Unknown | H18: Feature request for Lambda image attributes such as ImageUri; expected Nov 22. | J18: No telemetry | L18: =IF($B18="","",VLOOKUP($C18,Lists!$A$2:$B$10,2,FALSE)) -> #N/A
A19: MetLife, Inc. | B19: RedHat Hardened Images Support | C19: {=IF($B19="","",INDEX('Gap reference'!$C$2:$C$60,MATCH($B19,'Gap reference'!$A$2:$A$60,0)))} -> #N/A | D19: {=IF($B19="","",INDEX('Gap reference'!$D$2:$D$60,MATCH($B19,'Gap reference'!$A$2:$A$60,0)))} -> #N/A | E19: {=IF($B19="","",INDEX('Gap reference'!$G$2:$G$60,MATCH($B19,'Gap reference'!$A$2:$A$60,0)))} -> #N/A | H19: About half of the Docker images being built and deployed by MetLife use RedHat Hardened Images as base. Current version of CortexCLI and CC Intelligence feed does not allow for complete SBOM extraction and vulnerability detection respectively.
A20: Equinix, Inc. | B20: DSPM large file set scanning w/ MIP labeling | C20: {=IF($B20="","",INDEX('Gap reference'!$C$2:$C$60,MATCH($B20,'Gap reference'!$A$2:$A$60,0)))} -> #N/A | D20: {=IF($B20="","",INDEX('Gap reference'!$D$2:$D$60,MATCH($B20,'Gap reference'!$A$2:$A$60,0)))} -> #N/A | E20: {=IF($B20="","",INDEX('Gap reference'!$G$2:$G$60,MATCH($B20,'Gap reference'!$A$2:$A$60,0)))} -> #N/A | H20: DSPM MIP Labeling and Ability to scan large number of files. Partially solved, still to be delivered and demo-ed to the customer
A21: John Hancock Financial Services, Inc. | B21: Cortex CLI: --policy-metadata-filter (policy labels) | C21: {=IF($B21="","",INDEX('Gap reference'!$C$2:$C$60,MATCH($B21,'Gap reference'!$A$2:$A$60,0)))} -> #N/A | D21: {=IF($B21="","",INDEX('Gap reference'!$D$2:$D$60,MATCH($B21,'Gap reference'!$A$2:$A$60,0)))} -> #N/A | E21: {=IF($B21="","",INDEX('Gap reference'!$G$2:$G$60,MATCH($B21,'Gap reference'!$A$2:$A$60,0)))} -> #N/A | F21: No telemetry | G21: Hard blocker | H21: Pipelines select custom YAML IaC policies by label at build time (--policy-metadata-filter policy.label). Cortex CLI lacks the flag. P0, customer-confirmed (TAC 4186899). | I21: None. DC confirmed no workaround (Oct 21). | J21: No telemetry | L21: =IF($B21="","",VLOOKUP($C21,Lists!$A$2:$B$10,2,FALSE)) -> #N/A | M21: =IF(AND($G21="Hard blocker",$L21=9),"Yes","") -> #N/A | N21: 46316 | O21: Split from the combined CLI flags row. Product list to Elad Oct 27; PM owner to be named by product.
A22: John Hancock Financial Services, Inc. | B22: End-of-life / end-of-sale package detection | C22: {=IF($B22="","",INDEX('Gap reference'!$C$2:$C$60,MATCH($B22,'Gap reference'!$A$2:$A$60,0)))} -> #N/A | D22: {=IF($B22="","",INDEX('Gap reference'!$D$2:$D$60,MATCH($B22,'Gap reference'!$A$2:$A$60,0)))} -> #N/A | E22: {=IF($B22="","",INDEX('Gap reference'!$G$2:$G$60,MATCH($B22,'Gap reference'!$A$2:$A$60,0)))} -> #N/A | F22: No telemetry | G22: Hard blocker | H22: End-of-life and end-of-sale package detection in the CWP and AppSec scanners. Customer-confirmed upgrade blocker (TAC 4186938, Asana FR). Customer vulnerability team uses Qualys for this. | I22: Prisma Cloud today: PS-built scripts. No Cortex Cloud equivalent. | J22: No telemetry | L22: =IF($B22="","",VLOOKUP($C22,Lists!$A$2:$B$10,2,FALSE)) -> #N/A | M22: =IF(AND($G22="Hard blocker",$L22=9),"Yes","") -> #N/A | N22: 46316 | O22: Routes to product through Elad (Gil Kedem scope is ADS, Outpost, CloudScan).
A23: John Hancock Financial Services, Inc. | B23: Cortex CLI finding suppression | C23: {=IF($B23="","",INDEX('Gap reference'!$C$2:$C$60,MATCH($B23,'Gap reference'!$A$2:$A$60,0)))} -> #N/A | D23: {=IF($B23="","",INDEX('Gap reference'!$D$2:$D$60,MATCH($B23,'Gap reference'!$A$2:$A$60,0)))} -> #N/A | E23: {=IF($B23="","",INDEX('Gap reference'!$G$2:$G$60,MATCH($B23,'Gap reference'!$A$2:$A$60,0)))} -> #N/A | F23: No telemetry | G23: Hard blocker | H23: Suppression of Cortex CLI findings (GitHub Action AppSec integration). Core day-to-day IaC control; customer must validate before team leave in December. Support case 04184944. | I23: Developer suppressions until Posture Policy Exception lands (support: scheduled for tenant Nov 15, field). | J23: No telemetry | L23: =IF($B23="","",VLOOKUP($C23,Lists!$A$2:$B$10,2,FALSE)) -> #N/A | M23: =IF(AND($G23="Hard blocker",$L23=9),"Yes","") -> #N/A | N23: 46316 | O23: Planned release blank until product confirms; Nov 15 is support's date (field). Validate the Suppress action seen in AppSec CI/CD Runs against this requirement.
A24: John Hancock Financial Services, Inc. | B24: Cloud onboarding via API | C24: {=IF($B24="","",INDEX('Gap reference'!$C$2:$C$60,MATCH($B24,'Gap reference'!$A$2:$A$60,0)))} -> TBC | D24: {=IF($B24="","",INDEX('Gap reference'!$D$2:$D$60,MATCH($B24,'Gap reference'!$A$2:$A$60,0)))} -> Major blocker | E24: {=IF($B24="","",INDEX('Gap reference'!$G$2:$G$60,MATCH($B24,'Gap reference'!$A$2:$A$60,0)))} -> Eyal Rotberg | F24: No telemetry | G24: Workaround accepted | H24: Manual Azure onboarding with minimal permissions, no write/action/delete (former COE 748). Customer completed phases 1 to 4 of the manual onboarding guide on Oct 21 (platform and registry roles at management group, data and KSPM roles on test subscription). | I24: Manual onboarding guide; phase 5 registration (API call) run with PS. | J24: No telemetry | L24: =IF($B24="","",VLOOKUP($C24,Lists!$A$2:$B$10,2,FALSE)) -> 9 | M24: =IF(AND($G24="Hard blocker",$L24=9),"Yes","") | N24: 46316 | O24: Supported since the September release (field, Ali). Phase 5 pending PS staffing.
A25: John Hancock Financial Services, Inc. | B25: Azure BYO Event Hub | C25: {=IF($B25="","",INDEX('Gap reference'!$C$2:$C$60,MATCH($B25,'Gap reference'!$A$2:$A$60,0)))} -> Oct 2026 | D25: {=IF($B25="","",INDEX('Gap reference'!$D$2:$D$60,MATCH($B25,'Gap reference'!$A$2:$A$60,0)))} -> Major blocker | E25: {=IF($B25="","",INDEX('Gap reference'!$G$2:$G$60,MATCH($B25,'Gap reference'!$A$2:$A$60,0)))} -> Ashwin Manekar | F25: Not flagged | G25: Unknown | H25: Customer wants audit logs from existing central Event Hubs across subscriptions; created a test Event Hub per the guide. Open: management group vs subscription activity logs; cross-subscription ingestion. | J25: No, used but not flagged | L25: =IF($B25="","",VLOOKUP($C25,Lists!$A$2:$B$10,2,FALSE)) -> 1 | M25: =IF(AND($G25="Hard blocker",$L25=9),"Yes","") | N25: 46316 | O25: Waiting on customer Event Hub diagram and PM answer (Avishai).
A26: John Hancock Financial Services, Inc. | B26: Lightweight agent | C26: {=IF($B26="","",INDEX('Gap reference'!$C$2:$C$60,MATCH($B26,'Gap reference'!$A$2:$A$60,0)))} -> Oct 2026 | D26: {=IF($B26="","",INDEX('Gap reference'!$D$2:$D$60,MATCH($B26,'Gap reference'!$A$2:$A$60,0)))} -> Major blocker | E26: {=IF($B26="","",INDEX('Gap reference'!$G$2:$G$60,MATCH($B26,'Gap reference'!$A$2:$A$60,0)))} -> Daphna Shemesh | F26: No telemetry | G26: Unknown | H26: About half of Prisma Cloud credits are on AKS; every AKS environment runs the Defender in alert mode (CIS compliance and vulnerability scanning). Customer needs a quantified XDR agent footprint for its business case (COE 749). | J26: No telemetry | L26: =IF($B26="","",VLOOKUP($C26,Lists!$A$2:$B$10,2,FALSE)) -> 1 | M26: =IF(AND($G26="Hard blocker",$L26=9),"Yes","") | N26: 46316 | O26: Plan: measure the agent on one representative AKS cluster in the test migration. Agent CWP components must be in the customer's approved software catalog to deploy at scale.
A27: John Hancock Financial Services, Inc. | B27: Other (not on gap list) | C27: {=IF($B27="","",INDEX('Gap reference'!$C$2:$C$60,MATCH($B27,'Gap reference'!$A$2:$A$60,0)))} -> #N/A | D27: {=IF($B27="","",INDEX('Gap reference'!$D$2:$D$60,MATCH($B27,'Gap reference'!$A$2:$A$60,0)))} -> #N/A | E27: {=IF($B27="","",INDEX('Gap reference'!$G$2:$G$60,MATCH($B27,'Gap reference'!$A$2:$A$60,0)))} -> #N/A | F27: No telemetry | G27: Unknown | H27: Pipeline image gating: non-compliant images must not deploy after cutover. Admission control sits in the Kubernetes connector posture management (Policy Enforcement by the Admission Controller, documented). | J27: No telemetry | L27: =IF($B27="","",VLOOKUP($C27,Lists!$A$2:$B$10,2,FALSE)) -> #N/A | M27: =IF(AND($G27="Hard blocker",$L27=9),"Yes","") -> #N/A | N27: 46316 | O27: Production gate; validate in the test migration.
A28: John Hancock Financial Services, Inc. | B28: Other (not on gap list) | C28: {=IF($B28="","",INDEX('Gap reference'!$C$2:$C$60,MATCH($B28,'Gap reference'!$A$2:$A$60,0)))} -> #N/A | D28: {=IF($B28="","",INDEX('Gap reference'!$D$2:$D$60,MATCH($B28,'Gap reference'!$A$2:$A$60,0)))} -> #N/A | E28: {=IF($B28="","",INDEX('Gap reference'!$G$2:$G$60,MATCH($B28,'Gap reference'!$A$2:$A$60,0)))} -> #N/A | F28: No telemetry | G28: Unknown | H28: Kubernetes connector host compliance scanning, and whether containerd CIS support built for the Defender carried over to the XDR agent and connector. | J28: No telemetry | L28: =IF($B28="","",VLOOKUP($C28,Lists!$A$2:$B$10,2,FALSE)) -> #N/A | M28: =IF(AND($G28="Hard blocker",$L28=9),"Yes","") -> #N/A | N28: 46316 | O28: Written question to the KSPM PM.
A29: John Hancock Financial Services, Inc. | B29: JFrog subdomains | C29: {=IF($B29="","",INDEX('Gap reference'!$C$2:$C$60,MATCH($B29,'Gap reference'!$A$2:$A$60,0)))} -> Jan 2027 | D29: {=IF($B29="","",INDEX('Gap reference'!$D$2:$D$60,MATCH($B29,'Gap reference'!$A$2:$A$60,0)))} -> Validate in discovery | E29: {=IF($B29="","",INDEX('Gap reference'!$G$2:$G$60,MATCH($B29,'Gap reference'!$A$2:$A$60,0)))} -> Elad Shuster | F29: No telemetry | G29: Unknown | H29: JFrog Artifactory self-hosted in Azure, private. Product (Avishai) confirmed CloudScan covers private ACR and JFrog; JFrog with subdomains needs admin credentials, path-based does not. | J29: No telemetry | L29: =IF($B29="","",VLOOKUP($C29,Lists!$A$2:$B$10,2,FALSE)) -> 2 | M29: =IF(AND($G29="Hard blocker",$L29=9),"Yes","") | N29: 46316 | O29: Confirm whether Manulife's JFrog uses subdomains or paths.
A30: John Hancock Financial Services, Inc. | B30: Other (not on gap list) | C30: {=IF($B30="","",INDEX('Gap reference'!$C$2:$C$60,MATCH($B30,'Gap reference'!$A$2:$A$60,0)))} -> #N/A | D30: {=IF($B30="","",INDEX('Gap reference'!$D$2:$D$60,MATCH($B30,'Gap reference'!$A$2:$A$60,0)))} -> #N/A | E30: {=IF($B30="","",INDEX('Gap reference'!$G$2:$G$60,MATCH($B30,'Gap reference'!$A$2:$A$60,0)))} -> #N/A | F30: No telemetry | G30: Unknown | H30: Evaluate policies from a local git repo (policy as code) in Cortex CLI (TAC 4186920). | J30: No telemetry | L30: =IF($B30="","",VLOOKUP($C30,Lists!$A$2:$B$10,2,FALSE)) -> #N/A | M30: =IF(AND($G30="Hard blocker",$L30=9),"Yes","") -> #N/A | O30: From account issues tracker; not yet confirmed as a blocker.
A31: John Hancock Financial Services, Inc. | B31: Other (not on gap list) | C31: {=IF($B31="","",INDEX('Gap reference'!$C$2:$C$60,MATCH($B31,'Gap reference'!$A$2:$A$60,0)))} -> #N/A | D31: {=IF($B31="","",INDEX('Gap reference'!$D$2:$D$60,MATCH($B31,'Gap reference'!$A$2:$A$60,0)))} -> #N/A | E31: {=IF($B31="","",INDEX('Gap reference'!$G$2:$G$60,MATCH($B31,'Gap reference'!$A$2:$A$60,0)))} -> #N/A | F31: No telemetry | G31: Unknown | H31: Nested Terraform module scanning (TAC 4186936; prior RFE PANWRFE-I-1429). | J31: No telemetry | L31: =IF($B31="","",VLOOKUP($C31,Lists!$A$2:$B$10,2,FALSE)) -> #N/A | M31: =IF(AND($G31="Hard blocker",$L31=9),"Yes","") -> #N/A | O31: From account issues tracker; not yet confirmed as a blocker.
A32: John Hancock Financial Services, Inc. | B32: Other (not on gap list) | C32: {=IF($B32="","",INDEX('Gap reference'!$C$2:$C$60,MATCH($B32,'Gap reference'!$A$2:$A$60,0)))} -> #N/A | D32: {=IF($B32="","",INDEX('Gap reference'!$D$2:$D$60,MATCH($B32,'Gap reference'!$A$2:$A$60,0)))} -> #N/A | E32: {=IF($B32="","",INDEX('Gap reference'!$G$2:$G$60,MATCH($B32,'Gap reference'!$A$2:$A$60,0)))} -> #N/A | F32: No telemetry | G32: Unknown | H32: Cortex CLI output shows failed checks only, not passed (TAC 4186889). | J32: No telemetry | L32: =IF($B32="","",VLOOKUP($C32,Lists!$A$2:$B$10,2,FALSE)) -> #N/A | M32: =IF(AND($G32="Hard blocker",$L32=9),"Yes","") -> #N/A | O32: From account issues tracker.
A33: John Hancock Financial Services, Inc. | B33: Other (not on gap list) | C33: {=IF($B33="","",INDEX('Gap reference'!$C$2:$C$60,MATCH($B33,'Gap reference'!$A$2:$A$60,0)))} -> #N/A | D33: {=IF($B33="","",INDEX('Gap reference'!$D$2:$D$60,MATCH($B33,'Gap reference'!$A$2:$A$60,0)))} -> #N/A | E33: {=IF($B33="","",INDEX('Gap reference'!$G$2:$G$60,MATCH($B33,'Gap reference'!$A$2:$A$60,0)))} -> #N/A | F33: No telemetry | G33: Unknown | H33: Suppress an IaC issue directly from the console link (TAC 4186880). | J33: No telemetry | L33: =IF($B33="","",VLOOKUP($C33,Lists!$A$2:$B$10,2,FALSE)) -> #N/A | M33: =IF(AND($G33="Hard blocker",$L33=9),"Yes","") -> #N/A | O33: From account issues tracker.
